Workbook

Sheet Part 1
A1: IdPeritoOriginale | B1: TipoPersona | C1: TipoPerito | D1: IdPerito | E1: OperativitaSol | F1: NOME | G1: CognomeRagSoc | H1: Sesso | I1: PartitaIva | J1: CodiceFiscale | K1: Categoria | L1: Citta | M1: Provincia | N1: CAP | O1: INDIRIZZO | P1: Telefono | Q1: Cellulare | R1: Fax | S1: Mail1 | T1: MailPec | U1: DataInizioAlbo | V1: DataFineAlbo | W1: FlagAlbo | X1: CldPrimario | Y1: FatturazioneProvincia | Z1: FatturazioneCitta | AA1: FatturazioneIndirizzo | AB1: FatturazioneCap | AC1: FatturazioneRegioneSociale | AD1: FatturazioneTipoPersona | AE1: CodiceProfessione | AF1: IBAN | AG1: RegimeFiscale
A2: 0001 | B2: 1 - PERSONA FISICA | C2: 1 - AUTO | E2: 0 - NO | F2: MARCO | G2: BRANCATO | H2: M - MASCHIO | I2: 08180140017 | J2: BRNMCG75R26L219P | K2: 1 - AUTO | L2: C860 - COLLEGNO | M2: TO | N2: 10093 | O2: VIA M. BUONARROTI 1 | Q2: 3498115187 | R2: 011748395 | S2: INFO@MARCOBRANCATO.IT | U2: 01/01/1900 | V2: 08/10/2018 | W2: 0 - NO | Y2: TO | Z2: C860 - COLLEGNO | AA2: VIA M. BUONARROTI 1 | AB2: 10093 | AC2: BRANCATO | AD2: 1 - PERSONA FISICA | AE2: 10 - Perito Auto | AF2: IT98T0200801127000020040661 | AG2: 25 - Soggetto a sola IVA 22
A3: 0002 | B3: 1 - PERSONA FISICA | C3: 1 - AUTO | E3: 0 - NO | F3: ANDREA | G3: RIZZO | H3: F - FEMMINA | K3: 1 - AUTO | L3: L219 - TORINO | M3: TO | N3: 10141 | O3: VIA CARDINALE FOSSATI, 6 | R3: 01119826963 | S3: INFO@STUDIOANDREARIZZO.COM | U3: 01/01/1900 | V3: 13/01/2025 | W3: 0 - NO | Y3: TO | Z3: L219 - TORINO | AA3: VIA CARDINALE FOSSATI, 6 | AB3: 10141 | AC3: RIZZO | AD3: 1 - PERSONA FISICA | AE3: 10 - Perito Auto | AF3: IT70W0623001130000035642616 | AG3: 25 - Soggetto a sola IVA 22
A4: 0006 | B4: 0 - PERSONA GIURIDICA | C4: 1 - AUTO | E4: 0 - NO | G4: TORRISI | H4: S - SOCIETA | I4: 01932960022 | J4: 01932960022 | K4: 1 - AUTO | L4: A859 - BIELLA | M4: BI | N4: 13900 | O4: VIA PIETRO MICCA 31/D | U4: 01/11/2012 | V4: 31/12/2018 | W4: 0 - NO | Y4: BI | Z4: A859 - BIELLA | AA4: VIA PIETRO MICCA 31/D | AB4: 13900 | AC4: TORRISI | AD4: 0 - PERSONA GIURIDICA | AE4: 10 - Perito Auto | AF4: IT41G0326822303052932988620
A5: 003 | B5: 0 - PERSONA GIURIDICA | E5: 0 - NO | G5: FEDERPERITIGEST S.R.L. | H5: S - SOCIETA | I5: 02131920189 | L5: A473 - ASSAGO | M5: MI | N5: 20090 | O5: MILANO FIORI STRADA 1, PALAZZO F1 | R5: 800801662 | S5: INCARICHI@FEDERPERITIGEST.IT | U5: 01/01/1900 | V5: 31/01/1990 | W5: 0 - NO | Y5: MI | Z5: A473 - ASSAGO | AA5: MILANO FIORI STRADA 1, PALAZZO F1 | AB5: 20090 | AC5: FEDERPERITIGEST S.R.L. | AD5: 0 - PERSONA GIURIDICA | AF5: IT67O0306933684100000003505
A6: 004 | B6: 0 - PERSONA GIURIDICA | E6: 0 - NO | G6: CREMONA STIME SRL | H6: S - SOCIETA | I6: 01247820192 | U6: 02/02/2006 | V6: 31/12/2017 | W6: 0 - NO | AC6: CREMONA STIME SRL | AD6: 0 - PERSONA GIURIDICA | AF6: IT05V0350011403000000022222
A7: 005 | B7: 0 - PERSONA GIURIDICA | E7: 0 - NO | G7: GRUPPO DI LAVORO IN UN INTERNO SRL | H7: S - SOCIETA | I7: 12648430150 | L7: F205 - MILANO | M7: MI | N7: 20121 | O7: VIA SENATO 18 | R7: 0276006892 | U7: 01/01/1900 | V7: 31/12/1990 | W7: 0 - NO | Y7: MI | Z7: F205 - MILANO | AA7: VIA SENATO 18 | AB7: 20121 | AC7: GRUPPO DI LAVORO IN UN INTERNO SRL | AD7: 0 - PERSONA GIURIDICA | AF7: IT60V0504856070000000001477
A8: 007 | B8: 0 - PERSONA GIURIDICA | E8: 0 - NO | G8: DE ANGELI DANIELE | H8: S - SOCIETA | I8: 00690290085 | L8: E290 - IMPERIA | M8: IM | N8: 18100 | O8: VIA FOCE 60 | R8: 1782710985 | S8: DANIELE. | U8: 01/07/2012 | V8: 31/12/2020 | W8: 0 - NO | Y8: IM | Z8: E290 - IMPERIA | AA8: VIA FOCE 60 | AB8: 18100 | AC8: DE ANGELI DANIELE | AD8: 0 - PERSONA GIURIDICA | AF8: IT45K0200810502000100273016
A9: 008 | B9: 1 - PERSONA FISICA | E9: 0 - NO | F9: MASSIMO | G9: GATTI | H9: M - MASCHIO | I9: 01011960992 | L9: C621 - CHIAVARI | M9: GE | N9: 16043 | O9: VIA VENETO 10/2 | S9: PERITOGATTI@LIBERO.IT | U9: 01/07/2012 | V9: 31/12/2021 | W9: 0 - NO | Y9: GE | Z9: C621 - CHIAVARI | AA9: VIA VENETO 10/2 | AB9: 16043 | AC9: GATTI | AD9: 1 - PERSONA FISICA | AF9: IT92U0552632010000000011480
A10: 009 | B10: 0 - PERSONA GIURIDICA | E10: 0 - NO | G10: STRATTA | H10: S - SOCIETA | I10: 10206540014 | L10: E379 - IVREA | M10: TO | N10: 10015 | O10: VIA AOSTA 67 | R10: 012549158 | U10: 01/07/2012 | V10: 06/06/2023 | W10: 0 - NO | Y10: TO | Z10: E379 - IVREA | AA10: VIA AOSTA 67 | AB10: 10015 | AC10: STRATTA | AD10: 0 - PERSONA GIURIDICA | AF10: IT61G0306931570100000019012
A11: 010 | B11: 0 - PERSONA GIURIDICA | E11: 0 - NO | G11: ED ENGINEERING DATA SRL | H11: S - SOCIETA | I11: 05425530010 | L11: L219 - TORINO | M11: TO | N11: 10128 | O11: VIA GIANBATTISTA VICO 21 | S11: TRASPERIZIE@ENGINEERINGDATA.IT | U11: 01/01/1900 | V11: 05/06/2023 | W11: 0 - NO | Y11: TO | Z11: L219 - TORINO | AA11: VIA GIANBATTISTA VICO 21 | AB11: 10128 | AC11: ED ENGINEERING DATA SRL | AD11: 0 - PERSONA GIURIDICA | AF11: IT20H0315901000801570150006
A12: 011 | B12: 0 - PERSONA GIURIDICA | E12: 0 - NO | F12: ENRICO | G12: ABRATE ENRICO | H12: S - SOCIETA | I12: 03192540049 | J12: BRTNRC86E161470Z | L12: I470 - SAVIGLIANO | M12: CN | N12: 12038 | O12: VIA TRENTO, 14 | U12: 01/01/1900 | V12: 06/06/2023 | W12: 0 - NO | Y12: CN | Z12: I470 - SAVIGLIANO | AA12: VIA TRENTO, 14 | AB12: 12038 | AC12: ABRATE ENRICO | AD12: 0 - PERSONA GIURIDICA
A13: 012 | B13: 0 - PERSONA GIURIDICA | E13: 0 - NO | F13: GIACOMO | G13: AGNELLI GIACOMO | H13: S - SOCIETA | I13: 01422820330 | J13: GNLGCM75T30G535A | L13: C053 - CASTEGGIO | M13: PV | N13: 27045 | O13: VIA TORINO, 17 | U13: 01/01/1900 | V13: 06/06/2023 | W13: 0 - NO | Y13: PV | Z13: C053 - CASTEGGIO | AA13: VIA TORINO, 17 | AB13: 27045 | AC13: AGNELLI GIACOMO | AD13: 0 - PERSONA GIURIDICA
A14: 013 | B14: 0 - PERSONA GIURIDICA | E14: 0 - NO | F14: PAOLA | G14: ARCHETTI PAOLA | H14: S - SOCIETA | I14: 03242440984 | J14: RCHPLA81L45B157G | L14: F672 - MONTICELLI BRUSATI | M14: BS | N14: 25040 | O14: VIA SAN FRANCESCO D'ASSISI, 48 | U14: 01/01/1900 | V14: 06/06/2023 | W14: 0 - NO | Y14: BS | Z14: F672 - MONTICELLI BRUSATI | AA14: VIA SAN FRANCESCO D'ASSISI, 48 | AB14: 25040 | AC14: ARCHETTI PAOLA | AD14: 0 - PERSONA GIURIDICA
A15: 014 | B15: 1 - PERSONA FISICA | E15: 0 - NO | F15: LUCA | G15: ASCANI | H15: M - MASCHIO | I15: 01482310552 | J15: SCNLCU85M27L117E | L15: A439 - ARRONE | M15: TR | N15: 05031 | O15: VOC.NASCIOLO, 13 | S15: P.LUCA.ASCANI@GMAIL.COM | U15: 01/01/1900 | V15: 06/06/2023 | W15: 0 - NO | Y15: TR | Z15: A439 - ARRONE | AA15: VOC.NASCIOLO, 13 | AB15: 05031 | AC15: ASCANI | AD15: 1 - PERSONA FISICA | AF15: IT27E0631572681000080000072
A16: 015 | B16: 0 - PERSONA GIURIDICA | E16: 0 - NO | F16: CAFFI | G16: AVOGADRI CAFFI | H16: S - SOCIETA | I16: 01545600197 | L16: I827 - SONCINO | M16: CR | N16: 26029 | O16: VIA REGINA DELLA SCALA 134A | U16: 01/01/1900 | V16: 06/06/2023 | W16: 0 - NO | Y16: CR | Z16: I827 - SONCINO | AA16: VIA REGINA DELLA SCALA 134A | AB16: 26029 | AC16: AVOGADRI CAFFI | AD16: 0 - PERSONA GIURIDICA
A17: 016 | B17: 0 - PERSONA GIURIDICA | E17: 0 - NO | F17: ANGELO | G17: BALDIRAGHI ANGELO | H17: S - SOCIETA | I17: 00997970181 | J17: BLDNGL43421G388I | L17: B824 - CURA CARPIGNANO | M17: PV | N17: 27010 | O17: VIA VOLTA, 33 | U17: 01/01/1900 | V17: 06/06/2023 | W17: 0 - NO | Y17: PV | Z17: B824 - CURA CARPIGNANO | AA17: VIA VOLTA, 33 | AB17: 27010 | AC17: BALDIRAGHI ANGELO | AD17: 0 - PERSONA GIURIDICA
A18: 017 | B18: 0 - PERSONA GIURIDICA | E18: 0 - NO | F18: RICCARDO | G18: BALDUCCI RICCARDO | H18: S - SOCIETA | I18: 01382970398 | J18: BLDRCR66H07D829B | L18: D829 - FUSIGNANO | M18: RA | N18: 48010 | O18: VIA MARTELLI, 12, | U18: 01/01/1900 | V18: 06/06/2023 | W18: 0 - NO | Y18: RA | Z18: D829 - FUSIGNANO | AA18: VIA MARTELLI, 12, | AB18: 48010 | AC18: BALDUCCI RICCARDO | AD18: 0 - PERSONA GIURIDICA
A19: 018 | B19: 0 - PERSONA GIURIDICA | E19: 0 - NO | F19: GIANCARLO | G19: BALESTRERI GIANCARLO | H19: S - SOCIETA | I19: 00908340193 | J19: BLSGCR62E30D50M | L19: I790 - SOLAROLO RAINERIO | M19: CR | N19: 26030 | O19: VIA GIUSEPPINA, 24 | U19: 01/01/1900 | V19: 06/06/2023 | W19: 0 - NO | Y19: CR | Z19: I790 - SOLAROLO RAINERIO | AA19: VIA GIUSEPPINA, 24 | AB19: 26030 | AC19: BALESTRERI GIANCARLO | AD19: 0 - PERSONA GIURIDICA
A20: 019 | B20: 1 - PERSONA FISICA | E20: 0 - NO | F20: LAURO | G20: BALLANI | H20: M - MASCHIO | J20: BLLLRA61S21E240A | L20: G782 - POLESELLA | M20: RO | N20: 45038 | O20: VIA FANTATI 19 | Q20: 3487849822 | U20: 01/01/1900 | V20: 06/06/2023 | W20: 0 - NO | Y20: RO | Z20: G782 - POLESELLA | AA20: VIA FANTATI 19 | AB20: 45038 | AC20: BALLANI | AD20: 1 - PERSONA FISICA | AF20: IT93M062256342007400793445S
A21: 020 | B21: 1 - PERSONA FISICA | E21: 0 - NO | F21: DAMASO | G21: BARBAGALLO | H21: M - MASCHIO | J21: BRBDMS71B08E017M | L21: E017 - GIARRE | M21: CT | N21: 95014 | O21: VIA GERARDO MARRONE 21 | S21: DAMASO_BARBA@YAHOO.COM | U21: 01/01/1900 | V21: 06/06/2023 | W21: 0 - NO | Y21: CT | Z21: E017 - GIARRE | AA21: VIA GERARDO MARRONE 21 | AB21: 95014 | AC21: BARBAGALLO | AD21: 1 - PERSONA FISICA
A22: 02019493 | B22: 1 - PERSONA FISICA | E22: 0 - NO | F22: MARGARETH | G22: DIGRANDI MARGARETH | H22: F - FEMMINA | I22: 06030620014 | J22: DGRMGR72E56F205G | L22: F205 - MILANO | M22: MI | N22: 20143 | O22: VIA S.G. COTTOLENGO, 7 | S22: margarethdigrandi@yahoo.it | U22: 17/07/2003 | V22: 01/10/2018 | W22: 0 - NO | Y22: MI | Z22: F205 - MILANO | AA22: VIA S.G. COTTOLENGO, 7 | AB22: 20143 | AC22: DIGRANDI MARGARETH | AD22: 1 - PERSONA FISICA | AF22: IT58Q0306909540000000167781
A23: 021 | B23: 1 - PERSONA FISICA | E23: 0 - NO | F23: ANDREA | G23: BARBETTA | J23: BRBNDR90E10D442D | L23: G224 - PADOVA | M23: PD | N23: 35040 | O23: VIA PAPA LUCIANI, 19 | U23: 01/01/1900 | V23: 06/06/2023 | W23: 0 - NO | Y23: PD | Z23: G224 - PADOVA | AA23: VIA PAPA LUCIANI, 19 | AB23: 35040 | AC23: BARBETTA | AD23: 1 - PERSONA FISICA | AF23: IT87Y0622562560100000007754
A24: 0214 | B24: 1 - PERSONA FISICA | E24: 0 - NO | F24: ALESSANDRA | G24: CALASCIBETTA | H24: F - FEMMINA | I24: 09307440017 | J24: CLSLSN74B44L219G | L24: L219 - TORINO | M24: TO | N24: 10126 | O24: VIA FEDERICO MENABREA 1 | S24: AVV.ALESSANDRACALASCIBETTA@OUTLOOK.COM | U24: 01/01/1900 | V24: 05/11/2021 | W24: 0 - NO | Y24: TO | Z24: L219 - TORINO | AA24: VIA FEDERICO MENABREA 1 | AB24: 10126 | AC24: CALASCIBETTA | AD24: 1 - PERSONA FISICA | AF24: IT17S0853001000000260106712 | AG24: 30 - Soggetto a IVA 22, R.A. e 4% Cassa Non Esente
A25: 0215 | B25: 1 - PERSONA FISICA | C25: 5 - LEGALE | E25: 0 - NO | F25: CLAUDIA | G25: BARONI | H25: F - FEMMINA | I25: 01800020990 | J25: BRNCLD80P48D969M | K25: 5 - LEGALE | L25: D969 - GENOVA | M25: GE | N25: 16128 | O25: CORSO AURELIO SAFFI 3/2 | Q25: 338.7063127 | S25: AVV.CLAUDIA.BARONI@GMAIL.COM | U25: 01/01/1900 | V25: 29/03/2022 | W25: 0 - NO | Y25: GE | Z25: D969 - GENOVA | AA25: CORSO AURELIO SAFFI 3/2 | AB25: 16128 | AC25: BARONI | AD25: 1 - PERSONA FISICA | AE25: 50 - Legali Fiduciari | AF25: IT50B0200801411000100333784 | AG25: 43 - NO SOGGETTO A R.A., NO IVA ART. 7, 4% CASSA ESENTE
A26: 0217 | B26: 1 - PERSONA FISICA | E26: 0 - NO | F26: IACOPO | G26: REBECCHI | H26: M - MASCHIO | J26: RBCCPI76P16B110U | L26: E897 - MANTOVA | M26: MN | N26: 46100 | O26: VIALE DELLA REPUBBLICA 17 | S26: AVV.REBECCHI@STUDIO-POLACCO.IT | U26: 01/01/1900 | V26: 31/12/2024 | W26: 0 - NO | Y26: MN | Z26: E897 - MANTOVA | AA26: VIALE DELLA REPUBBLICA 17 | AB26: 46100 | AC26: REBECCHI | AD26: 1 - PERSONA FISICA | AF26: IT68V0329601601000066453235
A27: 0218 | B27: 1 - PERSONA FISICA | C27: 5 - LEGALE | E27: 0 - NO | F27: FERNANDO | G27: BROGNA | H27: M - MASCHIO | I27: 03952190613 | J27: BRGFNN69H11F839E | K27: 5 - LEGALE | L27: B715 - CAPUA | M27: CE | N27: 81043 | O27: VIA VILLA VELLA 2 | S27: FERNANDO.BROGNA@VIRGILIO.IT | T27: FERNANDO.BROGNA@AVVOCATISMCV.IT | U27: 01/01/1900 | V27: 31/12/9999 | W27: 0 - NO | Y27: CE | Z27: B715 - CAPUA | AA27: VIA VILLA VELLA 2 | AB27: 81043 | AC27: BROGNA | AD27: 1 - PERSONA FISICA | AE27: 50 - Legali Fiduciari | AF27: IT52T0101074820100000004086 | AG27: 30 - Soggetto a IVA 22, R.A. e 4% Cassa Non Esente
A28: 022 | B28: 0 - PERSONA GIURIDICA | E28: 0 - NO | F28: FABRIZIO | G28: BARBIERI FABRIZIO | H28: S - SOCIETA | I28: 01108690296 | J28: BRBFRZ49S25I480W | L28: A059 - ADRIA | M28: RO | N28: 45011 | O28: VIA SAN VINCENZO DE PAOLI, 5/A | U28: 01/01/1900 | V28: 06/06/2023 | W28: 0 - NO | Y28: RO | Z28: A059 - ADRIA | AA28: VIA SAN VINCENZO DE PAOLI, 5/A | AB28: 45011 | AC28: BARBIERI FABRIZIO | AD28: 0 - PERSONA GIURIDICA
A29: 0222 | B29: 1 - PERSONA FISICA | E29: 0 - NO | F29: ANTONIO | G29: NEVOLA | H29: M - MASCHIO | I29: 07249520631 | J29: NVLNTN72A18F839R | L29: F839 - NAPOLI | M29: NA | N29: 80145 | O29: VIALE A. GRAMSCI 23 | Q29: 335.5444075 | S29: A.NEVOLA@STUDIOGIAQUINTO.IT | U29: 01/01/1900 | V29: 31/12/9999 | W29: 0 - NO | Y29: NA | Z29: F839 - NAPOLI | AA29: VIALE A. GRAMSCI 23 | AB29: 80145 | AC29: NEVOLA | AD29: 1 - PERSONA FISICA | AF29: IT67W0200803462000103625209 | AG29: 43 - NO SOGGETTO A R.A., NO IVA ART. 7, 4% CASSA ESENTE
A30: 0224 | B30: 0 - PERSONA GIURIDICA | C30: 1 - AUTO | E30: 0 - NO | G30: STUDIO SANTOVITO SNC | H30: S - SOCIETA | I30: 06035251211 | K30: 1 - AUTO | L30: B759 - CARDITO | M30: NA | N30: 80024 | O30: VIA P DONADIO 181 | R30: 081 19723315 | S30: PERIZIESANTOVITO@GMAIL.COM | U30: 01/01/1900 | V30: 01/03/2018 | W30: 0 - NO | Y30: NA | Z30: B759 - CARDITO | AA30: VIA P DONADIO 181 | AB30: 80024 | AC30: STUDIO SANTOVITO SNC | AD30: 0 - PERSONA GIURIDICA | AE30: 10 - Perito Auto | AF30: IT12Y0558403400000000000860
A31: 0227 | B31: 1 - PERSONA FISICA | C31: 5 - LEGALE | E31: 0 - NO | F31: ALESSANDRO | G31: BIANCHI | H31: M - MASCHIO | I31: 07052260010 | J31: BNCLSN67L19L219K | K31: 5 - LEGALE | L31: L219 - TORINO | M31: TO | N31: 10128 | O31: VIA LUIGI COLLI 3 | Q31: 335.5311134 | S31: AVVOCATOALESSANDROBIANCHI@GMAIL.COM | T31: ALESSANDROBIANCHI@PEC.ORDINEAVVOCATITORINO.IT | U31: 01/01/1900 | V31: 31/12/9999 | W31: 0 - NO | Y31: TO | Z31: L219 - TORINO | AA31: VIA LUIGI COLLI 3 | AB31: 10128 | AC31: BIANCHI | AD31: 1 - PERSONA FISICA | AE31: 50 - Legali Fiduciari | AF31: IT85Y0344001000000000318000 | AG31: 43 - NO SOGGETTO A R.A., NO IVA ART. 7, 4% CASSA ESENTE
A32: 0228 | B32: 1 - PERSONA FISICA | C32: 5 - LEGALE | E32: 0 - NO | F32: FRANCESCO PAOLO | G32: MOLINELLI | H32: M - MASCHIO | I32: 05395790826 | J32: MLNFNC78H24G273Y | K32: 5 - LEGALE | L32: G273 - PALERMO | M32: PA | N32: 90139 | O32: VIA ALFONSO BORRELLI N. 4 | Q32: 3288361457 | R32: 091 8040223 | S32: STUDIOMOLINELLI@OUTLOOK.COM | U32: 01/01/1900 | V32: 31/12/9999 | W32: 0 - NO | Y32: PA | Z32: G273 - PALERMO | AA32: VIA ALFONSO BORRELLI N. 4 | AB32: 90139 | AC32: MOLINELLI | AD32: 1 - PERSONA FISICA | AE32: 50 - Legali Fiduciari | AF32: IT40Z0301503200000000377904 | AG32: 30 - Soggetto a IVA 22, R.A. e 4% Cassa Non Esente
A33: 023 | B33: 1 - PERSONA FISICA | E33: 0 - NO | F33: ENRICO | G33: BARBINI | J33: BRBNRC61C11L359C | L33: L359 - TRECENTA | M33: RO | N33: 45027 | O33: VIA S. FRANCESCO, 54 | U33: 01/01/1900 | V33: 06/06/2023 | W33: 0 - NO | Y33: RO | Z33: L359 - TRECENTA | AA33: VIA S. FRANCESCO, 54 | AB33: 45027 | AC33: BARBINI | AD33: 1 - PERSONA FISICA
A34: 0230 | B34: 0 - PERSONA GIURIDICA | E34: 0 - NO | G34: PERITO ESTERNO AUTHOITALIA | H34: S - SOCIETA | I34: 11059320017 | J34: 11059320017 | L34: L219 - TORINO | M34: TO | N34: 10121 | O34: CORSO VINZAGLIO, 9 | S34: INCARICHI.NOBIS@AUTHOITALIA.IT | U34: 01/01/1900 | V34: 31/12/2021 | W34: 0 - NO | Y34: TO | Z34: L219 - TORINO | AA34: CORSO VINZAGLIO, 9 | AB34: 10121 | AC34: PERITO ESTERNO AUTHOITALIA | AD34: 0 - PERSONA GIURIDICA | AF34: IT77B0326830110052310012171 | AG34: 25 - Soggetto a sola IVA 22
A35: 0233 | B35: 1 - PERSONA FISICA | E35: 0 - NO | F35: GIUSY | G35: IRRERA | H35: F - FEMMINA | I35: 03154310837 | J35: RRRGSY77D52F158P | L35: F158 - MESSINA | M35: ME | N35: 98123 | O35: VIA G. LA FARINA 165 | R35: 090-2924092 | S35: GIUSYIRRERA@HOTMAIL.IT | U35: 01/01/1900 | V35: 25/03/2021 | W35: 0 - NO | Y35: ME | Z35: F158 - MESSINA | AA35: VIA G. LA FARINA 165 | AB35: 98123 | AC35: IRRERA | AD35: 1 - PERSONA FISICA | AF35: IT11T0200816530000101656893 | AG35: 25 - Soggetto a sola IVA 22
A36: 0234 | B36: 1 - PERSONA FISICA | C36: 4 - MEDICO | E36: 0 - NO | F36: GIAN LUCA | G36: BRUNO | H36: M - MASCHIO | I36: 01518740053 | J36: BRNGLC61A28L219V | K36: 4 - MEDICO | L36: L219 - TORINO | M36: TO | N36: 10121 | O36: CORSO GALILEO FERRARIS 2 | Q36: 3938338585 | S36: VALENTINA@SMLBRUNO.IT | U36: 01/01/1900 | V36: 31/12/9999 | W36: 0 - NO | Y36: TO | Z36: L219 - TORINO | AA36: CORSO GALILEO FERRARIS 2 | AB36: 10121 | AC36: BRUNO | AD36: 1 - PERSONA FISICA | AE36: 40 - Medici Privati | AF36: IT62T0608501004000000022277 | AG36: 28 - Soggetto a IVA 22 e Ritenuta d'Acconto
A37: 024 | B37: 0 - PERSONA GIURIDICA | E37: 0 - NO | F37: RENATO | G37: BASAGLIA RENATO | H37: S - SOCIETA | I37: 02073220200 | J37: BSGRNT46L29H771G | L37: E897 - MANTOVA | M37: MN | N37: 46100 | O37: VIA DEGLI SPALTI, 12 | U37: 01/01/1900 | V37: 06/06/2023 | W37: 0 - NO | Y37: MN | Z37: E897 - MANTOVA | AA37: VIA DEGLI SPALTI, 12 | AB37: 46100 | AC37: BASAGLIA RENATO | AD37: 0 - PERSONA GIURIDICA
A38: 0241 | B38: 1 - PERSONA FISICA | C38: 5 - LEGALE | E38: 0 - NO | F38: RAFFAELE | G38: NAPOLITANO | H38: M - MASCHIO | I38: 05569051211 | J38: NPLRFL75H13F839T | K38: 5 - LEGALE | L38: G795 - POLLENA TROCCHIA | M38: NA | N38: 80040 | O38: VIA S. TRINCHERA 28 | S38: AVV.RAFFAELENAPOLITANO@GMAIL.COM | U38: 01/01/1900 | V38: 31/12/9999 | W38: 0 - NO | Y38: NA | Z38: G795 - POLLENA TROCCHIA | AA38: VIA S. TRINCHERA 28 | AB38: 80040 | AC38: NAPOLITANO | AD38: 1 - PERSONA FISICA | AE38: 50 - Legali Fiduciari | AF38: IT07H0306234210000001464674 | AG38: 30 - Soggetto a IVA 22, R.A. e 4% Cassa Non Esente
A39: 0242 | B39: 1 - PERSONA FISICA | C39: 5 - LEGALE | E39: 0 - NO | F39: ANTONIO | G39: LIVERANI | H39: M - MASCHIO | I39: 11974071000 | J39: LVRNTN58T26L219H | K39: 5 - LEGALE | L39: H501 - ROMA | M39: RM | N39: 00189 | O39: VIA CASSIA 555 | Q39: 3358277804 | S39: ANT.LIVERANI@GMAIL.COM | U39: 01/01/1900 | V39: 31/12/9999 | W39: 0 - NO | Y39: RM | Z39: H501 - ROMA | AA39: VIA CASSIA 555 | AB39: 00189 | AC39: LIVERANI | AD39: 1 - PERSONA FISICA | AE39: 50 - Legali Fiduciari | AF39: IT71G0760103200001009884410 | AG39: 30 - Soggetto a IVA 22, R.A. e 4% Cassa Non Esente
A40: 0249 | B40: 0 - PERSONA GIURIDICA | E40: 0 - NO | G40: AUTHOITALIA SRL | H40: S - SOCIETA | I40: 11059320017 | J40: 11059320017 | L40: L219 - TORINO | M40: TO | N40: 10121 | O40: CORSO VINZAGLIO, 9 | Q40: 3343977276 | S40: AUTHORITY@AUTHOITALIA.IT | U40: 01/01/1900 | V40: 31/12/2021 | W40: 0 - NO | Y40: TO | Z40: L219 - TORINO | AA40: CORSO VINZAGLIO, 9 | AB40: 10121 | AC40: AUTHOITALIA SRL | AD40: 0 - PERSONA GIURIDICA | AF40: IT77B0326830110052310012171 | AG40: 25 - Soggetto a sola IVA 22
...

Sheet Riparte
A1: IdPeritoOriginale | B1: TipoPersona | C1: TipoPerito | D1: IdPerito | E1: OperativitaSol | F1: NOME | G1: CognomeRagSoc | H1: Sesso | I1: PartitaIva | J1: CodiceFiscale | K1: Categoria | L1: Citta | M1: Provincia | N1: CAP | O1: INDIRIZZO | P1: Telefono | Q1: Cellulare | R1: Fax | S1: Mail1 | T1: MailPec | U1: DataInizioAlbo | V1: DataFineAlbo | W1: FlagAlbo | X1: CldPrimario | Y1: FatturazioneProvincia | Z1: FatturazioneCitta | AA1: FatturazioneIndirizzo | AB1: FatturazioneCap | AC1: FatturazioneRegioneSociale | AD1: FatturazioneTipoPersona | AE1: CodiceProfessione | AF1: IBAN | AG1: RegimeFiscale | AH1: Origine_IdPerito | AI1: Controllo_Disponibilita | AJ1: Controllo_PrimoCarattere
A2: 0931 | B2: =_xlfn.XLOOKUP(A2,'Part 1'!A:A,'Part 1'!B:B) -> 0 - PERSONA GIURIDICA | C2: =_xlfn.XLOOKUP(A2,'Part 1'!A:A,'Part 1'!C:C) -> 3 - INVESTIGATORE/ACCERTATORE | D2: 30000 | E2: {=_xlfn.XLOOKUP($A2,'Part 1'!$A$2:$A$4305,INDEX('Part 1'!$A$2:$AG$4305,0,MATCH(E$1,'Part 1'!$1:$1,0)))} -> 0 - NO | F2: {=_xlfn.XLOOKUP($A2,'Part 1'!$A$2:$A$4305,INDEX('Part 1'!$A$2:$AG$4305,0,MATCH(F$1,'Part 1'!$1:$1,0)))} -> 0 | G2: {=_xlfn.XLOOKUP($A2,'Part 1'!$A$2:$A$4305,INDEX('Part 1'!$A$2:$AG$4305,0,MATCH(G$1,'Part 1'!$1:$1,0)))} -> CIEFFE INVESTIGAZIONI SRL | H2: {=_xlfn.XLOOKUP($A2,'Part 1'!$A$2:$A$4305,INDEX('Part 1'!$A$2:$AG$4305,0,MATCH(H$1,'Part 1'!$1:$1,0)))} -> S - SOCIETA | I2: {=_xlfn.XLOOKUP($A2,'Part 1'!$A$2:$A$4305,INDEX('Part 1'!$A$2:$AG$4305,0,MATCH(I$1,'Part 1'!$1:$1,0)))} -> 07857200963 | J2: {=_xlfn.XLOOKUP($A2,'Part 1'!$A$2:$A$4305,INDEX('Part 1'!$A$2:$AG$4305,0,MATCH(J$1,'Part 1'!$1:$1,0)))} -> 0 | K2: {=_xlfn.XLOOKUP($A2,'Part 1'!$A$2:$A$4305,INDEX('Part 1'!$A$2:$AG$4305,0,MATCH(K$1,'Part 1'!$1:$1,0)))} -> 3 - INVESTIGATORE/ACCERTATORE | L2: {=_xlfn.XLOOKUP($A2,'Part 1'!$A$2:$A$4305,INDEX('Part 1'!$A$2:$AG$4305,0,MATCH(L$1,'Part 1'!$1:$1,0)))} -> C523 - CERNUSCO SUL NAVIGLIO | ... AG2: {=_xlfn.XLOOKUP($A2,'Part 1'!$A$2:$A$4305,INDEX('Part 1'!$A$2:$AG$4305,0,MATCH(AG$1,'Part 1'!$1:$1,0)))} -> 25 - Soggetto a sola IVA 22 | AH2: Calcolato | AI2: =IF(D2="","",IF(COUNTIF('Periti SOL'!$A:$A,VALUE(D2))>0,IF(AH2="Calcolato","ERRORE: ID calcolato NON disponibile","OK - preesistente nei DB"),"OK")) -> OK | AJ2: =IF(D2="","",IF(LEFT(D2&"",1)=LEFT(C2&"",1),"OK","ERRORE: primo carattere diverso da TipoPerito")) -> OK
A3: 0218 | B3: =_xlfn.XLOOKUP(A3,'Part 1'!A:A,'Part 1'!B:B) -> 1 - PERSONA FISICA | C3: =_xlfn.XLOOKUP(A3,'Part 1'!A:A,'Part 1'!C:C) -> 5 - LEGALE | D3: 50001 | E3: {=_xlfn.XLOOKUP(A3,'Part 1'!$A$2:$A$4305,INDEX('Part 1'!$A$2:$AG$4305,0,MATCH(E$1,'Part 1'!$1:$1,0)))} -> 0 - NO | F3: {=_xlfn.XLOOKUP($A3,'Part 1'!$A$2:$A$4305,INDEX('Part 1'!$A$2:$AG$4305,0,MATCH(F$1,'Part 1'!$1:$1,0)))} -> FERNANDO | G3: {=_xlfn.XLOOKUP($A3,'Part 1'!$A$2:$A$4305,INDEX('Part 1'!$A$2:$AG$4305,0,MATCH(G$1,'Part 1'!$1:$1,0)))} -> BROGNA | H3: {=_xlfn.XLOOKUP($A3,'Part 1'!$A$2:$A$4305,INDEX('Part 1'!$A$2:$AG$4305,0,MATCH(H$1,'Part 1'!$1:$1,0)))} -> M - MASCHIO | I3: {=_xlfn.XLOOKUP($A3,'Part 1'!$A$2:$A$4305,INDEX('Part 1'!$A$2:$AG$4305,0,MATCH(I$1,'Part 1'!$1:$1,0)))} -> 03952190613 | J3: {=_xlfn.XLOOKUP($A3,'Part 1'!$A$2:$A$4305,INDEX('Part 1'!$A$2:$AG$4305,0,MATCH(J$1,'Part 1'!$1:$1,0)))} -> BRGFNN69H11F839E | K3: {=_xlfn.XLOOKUP($A3,'Part 1'!$A$2:$A$4305,INDEX('Part 1'!$A$2:$AG$4305,0,MATCH(K$1,'Part 1'!$1:$1,0)))} -> 5 - LEGALE | L3: {=_xlfn.XLOOKUP($A3,'Part 1'!$A$2:$A$4305,INDEX('Part 1'!$A$2:$AG$4305,0,MATCH(L$1,'Part 1'!$1:$1,0)))} -> B715 - CAPUA | M3: {=_xlfn.XLOOKUP($A3,'Part 1'!$A$2:$A$4305,INDEX('Part 1'!$A$2:$AG$4305,0,MATCH(M$1,'Part 1'!$1:$1,0)))} -> CE | ... AG3: {=_xlfn.XLOOKUP($A3,'Part 1'!$A$2:$A$4305,INDEX('Part 1'!$A$2:$AG$4305,0,MATCH(AG$1,'Part 1'!$1:$1,0)))} -> 30 - Soggetto a IVA 22, R.A. e 4% Cassa Non Esente | AH3: Calcolato | AI3: =IF(D3="","",IF(COUNTIF('Periti SOL'!$A:$A,VALUE(D3))>0,IF(AH3="Calcolato","ERRORE: ID calcolato NON disponibile","OK - preesistente nei DB"),"OK")) -> OK | AJ3: =IF(D3="","",IF(LEFT(D3&"",1)=LEFT(C3&"",1),"OK","ERRORE: primo carattere diverso da TipoPerito")) -> OK
A4: 0227 | B4: =_xlfn.XLOOKUP(A4,'Part 1'!A:A,'Part 1'!B:B) -> 1 - PERSONA FISICA | C4: =_xlfn.XLOOKUP(A4,'Part 1'!A:A,'Part 1'!C:C) -> 5 - LEGALE | D4: 50002 | E4: {=_xlfn.XLOOKUP(A4,'Part 1'!$A$2:$A$4305,INDEX('Part 1'!$A$2:$AG$4305,0,MATCH(E$1,'Part 1'!$1:$1,0)))} -> 0 - NO | F4: {=_xlfn.XLOOKUP($A4,'Part 1'!$A$2:$A$4305,INDEX('Part 1'!$A$2:$AG$4305,0,MATCH(F$1,'Part 1'!$1:$1,0)))} -> ALESSANDRO | G4: {=_xlfn.XLOOKUP($A4,'Part 1'!$A$2:$A$4305,INDEX('Part 1'!$A$2:$AG$4305,0,MATCH(G$1,'Part 1'!$1:$1,0)))} -> BIANCHI | H4: {=_xlfn.XLOOKUP($A4,'Part 1'!$A$2:$A$4305,INDEX('Part 1'!$A$2:$AG$4305,0,MATCH(H$1,'Part 1'!$1:$1,0)))} -> M - MASCHIO | I4: {=_xlfn.XLOOKUP($A4,'Part 1'!$A$2:$A$4305,INDEX('Part 1'!$A$2:$AG$4305,0,MATCH(I$1,'Part 1'!$1:$1,0)))} -> 07052260010 | J4: {=_xlfn.XLOOKUP($A4,'Part 1'!$A$2:$A$4305,INDEX('Part 1'!$A$2:$AG$4305,0,MATCH(J$1,'Part 1'!$1:$1,0)))} -> BNCLSN67L19L219K | K4: {=_xlfn.XLOOKUP($A4,'Part 1'!$A$2:$A$4305,INDEX('Part 1'!$A$2:$AG$4305,0,MATCH(K$1,'Part 1'!$1:$1,0)))} -> 5 - LEGALE | L4: {=_xlfn.XLOOKUP($A4,'Part 1'!$A$2:$A$4305,INDEX('Part 1'!$A$2:$AG$4305,0,MATCH(L$1,'Part 1'!$1:$1,0)))} -> L219 - TORINO | M4: {=_xlfn.XLOOKUP($A4,'Part 1'!$A$2:$A$4305,INDEX('Part 1'!$A$2:$AG$4305,0,MATCH(M$1,'Part 1'!$1:$1,0)))} -> TO | ... AG4: {=_xlfn.XLOOKUP($A4,'Part 1'!$A$2:$A$4305,INDEX('Part 1'!$A$2:$AG$4305,0,MATCH(AG$1,'Part 1'!$1:$1,0)))} -> 43 - NO SOGGETTO A R.A., NO IVA ART. 7, 4% CASSA ESENTE | AH4: Calcolato | AI4: =IF(D4="","",IF(COUNTIF('Periti SOL'!$A:$A,VALUE(D4))>0,IF(AH4="Calcolato","ERRORE: ID calcolato NON disponibile","OK - preesistente nei DB"),"OK")) -> OK | AJ4: =IF(D4="","",IF(LEFT(D4&"",1)=LEFT(C4&"",1),"OK","ERRORE: primo carattere diverso da TipoPerito")) -> OK
A5: 0228 | B5: =_xlfn.XLOOKUP(A5,'Part 1'!A:A,'Part 1'!B:B) -> 1 - PERSONA FISICA | C5: =_xlfn.XLOOKUP(A5,'Part 1'!A:A,'Part 1'!C:C) -> 5 - LEGALE | D5: 50005 | E5: {=_xlfn.XLOOKUP(A5,'Part 1'!$A$2:$A$4305,INDEX('Part 1'!$A$2:$AG$4305,0,MATCH(E$1,'Part 1'!$1:$1,0)))} -> 0 - NO | F5: {=_xlfn.XLOOKUP($A5,'Part 1'!$A$2:$A$4305,INDEX('Part 1'!$A$2:$AG$4305,0,MATCH(F$1,'Part 1'!$1:$1,0)))} -> FRANCESCO PAOLO | G5: {=_xlfn.XLOOKUP($A5,'Part 1'!$A$2:$A$4305,INDEX('Part 1'!$A$2:$AG$4305,0,MATCH(G$1,'Part 1'!$1:$1,0)))} -> MOLINELLI | H5: {=_xlfn.XLOOKUP($A5,'Part 1'!$A$2:$A$4305,INDEX('Part 1'!$A$2:$AG$4305,0,MATCH(H$1,'Part 1'!$1:$1,0)))} -> M - MASCHIO | I5: {=_xlfn.XLOOKUP($A5,'Part 1'!$A$2:$A$4305,INDEX('Part 1'!$A$2:$AG$4305,0,MATCH(I$1,'Part 1'!$1:$1,0)))} -> 05395790826 | J5: {=_xlfn.XLOOKUP($A5,'Part 1'!$A$2:$A$4305,INDEX('Part 1'!$A$2:$AG$4305,0,MATCH(J$1,'Part 1'!$1:$1,0)))} -> MLNFNC78H24G273Y | K5: {=_xlfn.XLOOKUP($A5,'Part 1'!$A$2:$A$4305,INDEX('Part 1'!$A$2:$AG$4305,0,MATCH(K$1,'Part 1'!$1:$1,0)))} -> 5 - LEGALE | L5: {=_xlfn.XLOOKUP($A5,'Part 1'!$A$2:$A$4305,INDEX('Part 1'!$A$2:$AG$4305,0,MATCH(L$1,'Part 1'!$1:$1,0)))} -> G273 - PALERMO | M5: {=_xlfn.XLOOKUP($A5,'Part 1'!$A$2:$A$4305,INDEX('Part 1'!$A$2:$AG$4305,0,MATCH(M$1,'Part 1'!$1:$1,0)))} -> PA | ... AG5: {=_xlfn.XLOOKUP($A5,'Part 1'!$A$2:$A$4305,INDEX('Part 1'!$A$2:$AG$4305,0,MATCH(AG$1,'Part 1'!$1:$1,0)))} -> 30 - Soggetto a IVA 22, R.A. e 4% Cassa Non Esente | AH5: Calcolato | AI5: =IF(D5="","",IF(COUNTIF('Periti SOL'!$A:$A,VALUE(D5))>0,IF(AH5="Calcolato","ERRORE: ID calcolato NON disponibile","OK - preesistente nei DB"),"OK")) -> OK | AJ5: =IF(D5="","",IF(LEFT(D5&"",1)=LEFT(C5&"",1),"OK","ERRORE: primo carattere diverso da TipoPerito")) -> OK
A6: 0234 | B6: =_xlfn.XLOOKUP(A6,'Part 1'!A:A,'Part 1'!B:B) -> 1 - PERSONA FISICA | C6: =_xlfn.XLOOKUP(A6,'Part 1'!A:A,'Part 1'!C:C) -> 4 - MEDICO | D6: 40000 | E6: {=_xlfn.XLOOKUP(A6,'Part 1'!$A$2:$A$4305,INDEX('Part 1'!$A$2:$AG$4305,0,MATCH(E$1,'Part 1'!$1:$1,0)))} -> 0 - NO | F6: {=_xlfn.XLOOKUP($A6,'Part 1'!$A$2:$A$4305,INDEX('Part 1'!$A$2:$AG$4305,0,MATCH(F$1,'Part 1'!$1:$1,0)))} -> GIAN LUCA | G6: {=_xlfn.XLOOKUP($A6,'Part 1'!$A$2:$A$4305,INDEX('Part 1'!$A$2:$AG$4305,0,MATCH(G$1,'Part 1'!$1:$1,0)))} -> BRUNO | H6: {=_xlfn.XLOOKUP($A6,'Part 1'!$A$2:$A$4305,INDEX('Part 1'!$A$2:$AG$4305,0,MATCH(H$1,'Part 1'!$1:$1,0)))} -> M - MASCHIO | I6: {=_xlfn.XLOOKUP($A6,'Part 1'!$A$2:$A$4305,INDEX('Part 1'!$A$2:$AG$4305,0,MATCH(I$1,'Part 1'!$1:$1,0)))} -> 01518740053 | J6: {=_xlfn.XLOOKUP($A6,'Part 1'!$A$2:$A$4305,INDEX('Part 1'!$A$2:$AG$4305,0,MATCH(J$1,'Part 1'!$1:$1,0)))} -> BRNGLC61A28L219V | K6: {=_xlfn.XLOOKUP($A6,'Part 1'!$A$2:$A$4305,INDEX('Part 1'!$A$2:$AG$4305,0,MATCH(K$1,'Part 1'!$1:$1,0)))} -> 4 - MEDICO | L6: {=_xlfn.XLOOKUP($A6,'Part 1'!$A$2:$A$4305,INDEX('Part 1'!$A$2:$AG$4305,0,MATCH(L$1,'Part 1'!$1:$1,0)))} -> L219 - TORINO | M6: {=_xlfn.XLOOKUP($A6,'Part 1'!$A$2:$A$4305,INDEX('Part 1'!$A$2:$AG$4305,0,MATCH(M$1,'Part 1'!$1:$1,0)))} -> TO | ... AG6: {=_xlfn.XLOOKUP($A6,'Part 1'!$A$2:$A$4305,INDEX('Part 1'!$A$2:$AG$4305,0,MATCH(AG$1,'Part 1'!$1:$1,0)))} -> 28 - Soggetto a IVA 22 e Ritenuta d'Acconto | AH6: Calcolato | AI6: =IF(D6="","",IF(COUNTIF('Periti SOL'!$A:$A,VALUE(D6))>0,IF(AH6="Calcolato","ERRORE: ID calcolato NON disponibile","OK - preesistente nei DB"),"OK")) -> OK | AJ6: =IF(D6="","",IF(LEFT(D6&"",1)=LEFT(C6&"",1),"OK","ERRORE: primo carattere diverso da TipoPerito")) -> OK
A7: 0241 | B7: =_xlfn.XLOOKUP(A7,'Part 1'!A:A,'Part 1'!B:B) -> 1 - PERSONA FISICA | C7: =_xlfn.XLOOKUP(A7,'Part 1'!A:A,'Part 1'!C:C) -> 5 - LEGALE | D7: 50007 | E7: {=_xlfn.XLOOKUP(A7,'Part 1'!$A$2:$A$4305,INDEX('Part 1'!$A$2:$AG$4305,0,MATCH(E$1,'Part 1'!$1:$1,0)))} -> 0 - NO | F7: {=_xlfn.XLOOKUP($A7,'Part 1'!$A$2:$A$4305,INDEX('Part 1'!$A$2:$AG$4305,0,MATCH(F$1,'Part 1'!$1:$1,0)))} -> RAFFAELE | G7: {=_xlfn.XLOOKUP($A7,'Part 1'!$A$2:$A$4305,INDEX('Part 1'!$A$2:$AG$4305,0,MATCH(G$1,'Part 1'!$1:$1,0)))} -> NAPOLITANO | H7: {=_xlfn.XLOOKUP($A7,'Part 1'!$A$2:$A$4305,INDEX('Part 1'!$A$2:$AG$4305,0,MATCH(H$1,'Part 1'!$1:$1,0)))} -> M - MASCHIO | I7: {=_xlfn.XLOOKUP($A7,'Part 1'!$A$2:$A$4305,INDEX('Part 1'!$A$2:$AG$4305,0,MATCH(I$1,'Part 1'!$1:$1,0)))} -> 05569051211 | J7: {=_xlfn.XLOOKUP($A7,'Part 1'!$A$2:$A$4305,INDEX('Part 1'!$A$2:$AG$4305,0,MATCH(J$1,'Part 1'!$1:$1,0)))} -> NPLRFL75H13F839T | K7: {=_xlfn.XLOOKUP($A7,'Part 1'!$A$2:$A$4305,INDEX('Part 1'!$A$2:$AG$4305,0,MATCH(K$1,'Part 1'!$1:$1,0)))} -> 5 - LEGALE | L7: {=_xlfn.XLOOKUP($A7,'Part 1'!$A$2:$A$4305,INDEX('Part 1'!$A$2:$AG$4305,0,MATCH(L$1,'Part 1'!$1:$1,0)))} -> G795 - POLLENA TROCCHIA | M7: {=_xlfn.XLOOKUP($A7,'Part 1'!$A$2:$A$4305,INDEX('Part 1'!$A$2:$AG$4305,0,MATCH(M$1,'Part 1'!$1:$1,0)))} -> NA | ... AG7: {=_xlfn.XLOOKUP($A7,'Part 1'!$A$2:$A$4305,INDEX('Part 1'!$A$2:$AG$4305,0,MATCH(AG$1,'Part 1'!$1:$1,0)))} -> 30 - Soggetto a IVA 22, R.A. e 4% Cassa Non Esente | AH7: Calcolato | AI7: =IF(D7="","",IF(COUNTIF('Periti SOL'!$A:$A,VALUE(D7))>0,IF(AH7="Calcolato","ERRORE: ID calcolato NON disponibile","OK - preesistente nei DB"),"OK")) -> OK | AJ7: =IF(D7="","",IF(LEFT(D7&"",1)=LEFT(C7&"",1),"OK","ERRORE: primo carattere diverso da TipoPerito")) -> OK
A8: 0242 | B8: =_xlfn.XLOOKUP(A8,'Part 1'!A:A,'Part 1'!B:B) -> 1 - PERSONA FISICA | C8: =_xlfn.XLOOKUP(A8,'Part 1'!A:A,'Part 1'!C:C) -> 5 - LEGALE | D8: 50009 | E8: {=_xlfn.XLOOKUP(A8,'Part 1'!$A$2:$A$4305,INDEX('Part 1'!$A$2:$AG$4305,0,MATCH(E$1,'Part 1'!$1:$1,0)))} -> 0 - NO | F8: {=_xlfn.XLOOKUP($A8,'Part 1'!$A$2:$A$4305,INDEX('Part 1'!$A$2:$AG$4305,0,MATCH(F$1,'Part 1'!$1:$1,0)))} -> ANTONIO | G8: {=_xlfn.XLOOKUP($A8,'Part 1'!$A$2:$A$4305,INDEX('Part 1'!$A$2:$AG$4305,0,MATCH(G$1,'Part 1'!$1:$1,0)))} -> LIVERANI | H8: {=_xlfn.XLOOKUP($A8,'Part 1'!$A$2:$A$4305,INDEX('Part 1'!$A$2:$AG$4305,0,MATCH(H$1,'Part 1'!$1:$1,0)))} -> M - MASCHIO | I8: {=_xlfn.XLOOKUP($A8,'Part 1'!$A$2:$A$4305,INDEX('Part 1'!$A$2:$AG$4305,0,MATCH(I$1,'Part 1'!$1:$1,0)))} -> 11974071000 | J8: {=_xlfn.XLOOKUP($A8,'Part 1'!$A$2:$A$4305,INDEX('Part 1'!$A$2:$AG$4305,0,MATCH(J$1,'Part 1'!$1:$1,0)))} -> LVRNTN58T26L219H | K8: {=_xlfn.XLOOKUP($A8,'Part 1'!$A$2:$A$4305,INDEX('Part 1'!$A$2:$AG$4305,0,MATCH(K$1,'Part 1'!$1:$1,0)))} -> 5 - LEGALE | L8: {=_xlfn.XLOOKUP($A8,'Part 1'!$A$2:$A$4305,INDEX('Part 1'!$A$2:$AG$4305,0,MATCH(L$1,'Part 1'!$1:$1,0)))} -> H501 - ROMA | M8: {=_xlfn.XLOOKUP($A8,'Part 1'!$A$2:$A$4305,INDEX('Part 1'!$A$2:$AG$4305,0,MATCH(M$1,'Part 1'!$1:$1,0)))} -> RM | ... AG8: {=_xlfn.XLOOKUP($A8,'Part 1'!$A$2:$A$4305,INDEX('Part 1'!$A$2:$AG$4305,0,MATCH(AG$1,'Part 1'!$1:$1,0)))} -> 30 - Soggetto a IVA 22, R.A. e 4% Cassa Non Esente | AH8: Calcolato | AI8: =IF(D8="","",IF(COUNTIF('Periti SOL'!$A:$A,VALUE(D8))>0,IF(AH8="Calcolato","ERRORE: ID calcolato NON disponibile","OK - preesistente nei DB"),"OK")) -> OK | AJ8: =IF(D8="","",IF(LEFT(D8&"",1)=LEFT(C8&"",1),"OK","ERRORE: primo carattere diverso da TipoPerito")) -> OK
A9: 0282 | B9: =_xlfn.XLOOKUP(A9,'Part 1'!A:A,'Part 1'!B:B) -> 1 - PERSONA FISICA | C9: =_xlfn.XLOOKUP(A9,'Part 1'!A:A,'Part 1'!C:C) -> 5 - LEGALE | D9: 50010 | E9: {=_xlfn.XLOOKUP(A9,'Part 1'!$A$2:$A$4305,INDEX('Part 1'!$A$2:$AG$4305,0,MATCH(E$1,'Part 1'!$1:$1,0)))} -> 0 - NO | F9: {=_xlfn.XLOOKUP($A9,'Part 1'!$A$2:$A$4305,INDEX('Part 1'!$A$2:$AG$4305,0,MATCH(F$1,'Part 1'!$1:$1,0)))} -> LUCIA | G9: {=_xlfn.XLOOKUP($A9,'Part 1'!$A$2:$A$4305,INDEX('Part 1'!$A$2:$AG$4305,0,MATCH(G$1,'Part 1'!$1:$1,0)))} -> PISCITELLI | H9: {=_xlfn.XLOOKUP($A9,'Part 1'!$A$2:$A$4305,INDEX('Part 1'!$A$2:$AG$4305,0,MATCH(H$1,'Part 1'!$1:$1,0)))} -> F - FEMMINA | I9: {=_xlfn.XLOOKUP($A9,'Part 1'!$A$2:$A$4305,INDEX('Part 1'!$A$2:$AG$4305,0,MATCH(I$1,'Part 1'!$1:$1,0)))} -> 03033690615 | J9: {=_xlfn.XLOOKUP($A9,'Part 1'!$A$2:$A$4305,INDEX('Part 1'!$A$2:$AG$4305,0,MATCH(J$1,'Part 1'!$1:$1,0)))} -> PSCLCU69P62I233T | K9: {=_xlfn.XLOOKUP($A9,'Part 1'!$A$2:$A$4305,INDEX('Part 1'!$A$2:$AG$4305,0,MATCH(K$1,'Part 1'!$1:$1,0)))} -> 5 - LEGALE | L9: {=_xlfn.XLOOKUP($A9,'Part 1'!$A$2:$A$4305,INDEX('Part 1'!$A$2:$AG$4305,0,MATCH(L$1,'Part 1'!$1:$1,0)))} -> B963 - CASERTA | M9: {=_xlfn.XLOOKUP($A9,'Part 1'!$A$2:$A$4305,INDEX('Part 1'!$A$2:$AG$4305,0,MATCH(M$1,'Part 1'!$1:$1,0)))} -> CE | ... AG9: {=_xlfn.XLOOKUP($A9,'Part 1'!$A$2:$A$4305,INDEX('Part 1'!$A$2:$AG$4305,0,MATCH(AG$1,'Part 1'!$1:$1,0)))} -> 30 - Soggetto a IVA 22, R.A. e 4% Cassa Non Esente | AH9: Calcolato | AI9: =IF(D9="","",IF(COUNTIF('Periti SOL'!$A:$A,VALUE(D9))>0,IF(AH9="Calcolato","ERRORE: ID calcolato NON disponibile","OK - preesistente nei DB"),"OK")) -> OK | AJ9: =IF(D9="","",IF(LEFT(D9&"",1)=LEFT(C9&"",1),"OK","ERRORE: primo carattere diverso da TipoPerito")) -> OK
A10: 0294 | B10: =_xlfn.XLOOKUP(A10,'Part 1'!A:A,'Part 1'!B:B) -> 0 - PERSONA GIURIDICA | C10: =_xlfn.XLOOKUP(A10,'Part 1'!A:A,'Part 1'!C:C) -> 2 - RE | D10: 20000 | E10: {=_xlfn.XLOOKUP(A10,'Part 1'!$A$2:$A$4305,INDEX('Part 1'!$A$2:$AG$4305,0,MATCH(E$1,'Part 1'!$1:$1,0)))} -> 0 - NO | F10: {=_xlfn.XLOOKUP($A10,'Part 1'!$A$2:$A$4305,INDEX('Part 1'!$A$2:$AG$4305,0,MATCH(F$1,'Part 1'!$1:$1,0)))} -> 0 | G10: {=_xlfn.XLOOKUP($A10,'Part 1'!$A$2:$A$4305,INDEX('Part 1'!$A$2:$AG$4305,0,MATCH(G$1,'Part 1'!$1:$1,0)))} -> DPF SRL | H10: {=_xlfn.XLOOKUP($A10,'Part 1'!$A$2:$A$4305,INDEX('Part 1'!$A$2:$AG$4305,0,MATCH(H$1,'Part 1'!$1:$1,0)))} -> S - SOCIETA | I10: {=_xlfn.XLOOKUP($A10,'Part 1'!$A$2:$A$4305,INDEX('Part 1'!$A$2:$AG$4305,0,MATCH(I$1,'Part 1'!$1:$1,0)))} -> 06031930016 | J10: {=_xlfn.XLOOKUP($A10,'Part 1'!$A$2:$A$4305,INDEX('Part 1'!$A$2:$AG$4305,0,MATCH(J$1,'Part 1'!$1:$1,0)))} -> 0 | K10: {=_xlfn.XLOOKUP($A10,'Part 1'!$A$2:$A$4305,INDEX('Part 1'!$A$2:$AG$4305,0,MATCH(K$1,'Part 1'!$1:$1,0)))} -> 2 - RE | L10: {=_xlfn.XLOOKUP($A10,'Part 1'!$A$2:$A$4305,INDEX('Part 1'!$A$2:$AG$4305,0,MATCH(L$1,'Part 1'!$1:$1,0)))} -> L219 - TORINO | M10: {=_xlfn.XLOOKUP($A10,'Part 1'!$A$2:$A$4305,INDEX('Part 1'!$A$2:$AG$4305,0,MATCH(M$1,'Part 1'!$1:$1,0)))} -> TO | ... AG10: {=_xlfn.XLOOKUP($A10,'Part 1'!$A$2:$A$4305,INDEX('Part 1'!$A$2:$AG$4305,0,MATCH(AG$1,'Part 1'!$1:$1,0)))} -> 25 - Soggetto a sola IVA 22 | AH10: Calcolato | AI10: =IF(D10="","",IF(COUNTIF('Periti SOL'!$A:$A,VALUE(D10))>0,IF(AH10="Calcolato","ERRORE: ID calcolato NON disponibile","OK - preesistente nei DB"),"OK")) -> OK | AJ10: =IF(D10="","",IF(LEFT(D10&"",1)=LEFT(C10&"",1),"OK","ERRORE: primo carattere diverso da TipoPerito")) -> OK
A11: 0308 | B11: =_xlfn.XLOOKUP(A11,'Part 1'!A:A,'Part 1'!B:B) -> 0 - PERSONA GIURIDICA | C11: =_xlfn.XLOOKUP(A11,'Part 1'!A:A,'Part 1'!C:C) -> 2 - RE | D11: 20003 | E11: {=_xlfn.XLOOKUP(A11,'Part 1'!$A$2:$A$4305,INDEX('Part 1'!$A$2:$AG$4305,0,MATCH(E$1,'Part 1'!$1:$1,0)))} -> 0 - NO | F11: {=_xlfn.XLOOKUP($A11,'Part 1'!$A$2:$A$4305,INDEX('Part 1'!$A$2:$AG$4305,0,MATCH(F$1,'Part 1'!$1:$1,0)))} -> 0 | G11: {=_xlfn.XLOOKUP($A11,'Part 1'!$A$2:$A$4305,INDEX('Part 1'!$A$2:$AG$4305,0,MATCH(G$1,'Part 1'!$1:$1,0)))} -> LERCARI SRL | H11: {=_xlfn.XLOOKUP($A11,'Part 1'!$A$2:$A$4305,INDEX('Part 1'!$A$2:$AG$4305,0,MATCH(H$1,'Part 1'!$1:$1,0)))} -> S - SOCIETA | I11: {=_xlfn.XLOOKUP($A11,'Part 1'!$A$2:$A$4305,INDEX('Part 1'!$A$2:$AG$4305,0,MATCH(I$1,'Part 1'!$1:$1,0)))} -> 07600220961 | J11: {=_xlfn.XLOOKUP($A11,'Part 1'!$A$2:$A$4305,INDEX('Part 1'!$A$2:$AG$4305,0,MATCH(J$1,'Part 1'!$1:$1,0)))} -> 0 | K11: {=_xlfn.XLOOKUP($A11,'Part 1'!$A$2:$A$4305,INDEX('Part 1'!$A$2:$AG$4305,0,MATCH(K$1,'Part 1'!$1:$1,0)))} -> 2 - RE | L11: {=_xlfn.XLOOKUP($A11,'Part 1'!$A$2:$A$4305,INDEX('Part 1'!$A$2:$AG$4305,0,MATCH(L$1,'Part 1'!$1:$1,0)))} -> F205 - MILANO | M11: {=_xlfn.XLOOKUP($A11,'Part 1'!$A$2:$A$4305,INDEX('Part 1'!$A$2:$AG$4305,0,MATCH(M$1,'Part 1'!$1:$1,0)))} -> MI | ... AG11: {=_xlfn.XLOOKUP($A11,'Part 1'!$A$2:$A$4305,INDEX('Part 1'!$A$2:$AG$4305,0,MATCH(AG$1,'Part 1'!$1:$1,0)))} -> 25 - Soggetto a sola IVA 22 | AH11: Calcolato | AI11: =IF(D11="","",IF(COUNTIF('Periti SOL'!$A:$A,VALUE(D11))>0,IF(AH11="Calcolato","ERRORE: ID calcolato NON disponibile","OK - preesistente nei DB"),"OK")) -> OK | AJ11: =IF(D11="","",IF(LEFT(D11&"",1)=LEFT(C11&"",1),"OK","ERRORE: primo carattere diverso da TipoPerito")) -> OK
A12: 0312 | B12: =_xlfn.XLOOKUP(A12,'Part 1'!A:A,'Part 1'!B:B) -> 1 - PERSONA FISICA | C12: =_xlfn.XLOOKUP(A12,'Part 1'!A:A,'Part 1'!C:C) -> 5 - LEGALE | D12: 50013 | E12: {=_xlfn.XLOOKUP(A12,'Part 1'!$A$2:$A$4305,INDEX('Part 1'!$A$2:$AG$4305,0,MATCH(E$1,'Part 1'!$1:$1,0)))} -> 0 - NO | F12: {=_xlfn.XLOOKUP($A12,'Part 1'!$A$2:$A$4305,INDEX('Part 1'!$A$2:$AG$4305,0,MATCH(F$1,'Part 1'!$1:$1,0)))} -> ANTONIO | G12: {=_xlfn.XLOOKUP($A12,'Part 1'!$A$2:$A$4305,INDEX('Part 1'!$A$2:$AG$4305,0,MATCH(G$1,'Part 1'!$1:$1,0)))} -> PETRAROLO | H12: {=_xlfn.XLOOKUP($A12,'Part 1'!$A$2:$A$4305,INDEX('Part 1'!$A$2:$AG$4305,0,MATCH(H$1,'Part 1'!$1:$1,0)))} -> M - MASCHIO | I12: {=_xlfn.XLOOKUP($A12,'Part 1'!$A$2:$A$4305,INDEX('Part 1'!$A$2:$AG$4305,0,MATCH(I$1,'Part 1'!$1:$1,0)))} -> 03951750615 | J12: {=_xlfn.XLOOKUP($A12,'Part 1'!$A$2:$A$4305,INDEX('Part 1'!$A$2:$AG$4305,0,MATCH(J$1,'Part 1'!$1:$1,0)))} -> PTRNTN59T14D228P | K12: {=_xlfn.XLOOKUP($A12,'Part 1'!$A$2:$A$4305,INDEX('Part 1'!$A$2:$AG$4305,0,MATCH(K$1,'Part 1'!$1:$1,0)))} -> 5 - LEGALE | L12: {=_xlfn.XLOOKUP($A12,'Part 1'!$A$2:$A$4305,INDEX('Part 1'!$A$2:$AG$4305,0,MATCH(L$1,'Part 1'!$1:$1,0)))} -> I234 - SANTA MARIA CAPUA VETERE | M12: {=_xlfn.XLOOKUP($A12,'Part 1'!$A$2:$A$4305,INDEX('Part 1'!$A$2:$AG$4305,0,MATCH(M$1,'Part 1'!$1:$1,0)))} -> CE | ... AG12: {=_xlfn.XLOOKUP($A12,'Part 1'!$A$2:$A$4305,INDEX('Part 1'!$A$2:$AG$4305,0,MATCH(AG$1,'Part 1'!$1:$1,0)))} -> 30 - Soggetto a IVA 22, R.A. e 4% Cassa Non Esente | AH12: Calcolato | AI12: =IF(D12="","",IF(COUNTIF('Periti SOL'!$A:$A,VALUE(D12))>0,IF(AH12="Calcolato","ERRORE: ID calcolato NON disponibile","OK - preesistente nei DB"),"OK")) -> OK | AJ12: =IF(D12="","",IF(LEFT(D12&"",1)=LEFT(C12&"",1),"OK","ERRORE: primo carattere diverso da TipoPerito")) -> OK
A13: 0320 | B13: =_xlfn.XLOOKUP(A13,'Part 1'!A:A,'Part 1'!B:B) -> 1 - PERSONA FISICA | C13: =_xlfn.XLOOKUP(A13,'Part 1'!A:A,'Part 1'!C:C) -> 5 - LEGALE | D13: 50014 | E13: {=_xlfn.XLOOKUP(A13,'Part 1'!$A$2:$A$4305,INDEX('Part 1'!$A$2:$AG$4305,0,MATCH(E$1,'Part 1'!$1:$1,0)))} -> 0 - NO | F13: {=_xlfn.XLOOKUP($A13,'Part 1'!$A$2:$A$4305,INDEX('Part 1'!$A$2:$AG$4305,0,MATCH(F$1,'Part 1'!$1:$1,0)))} -> VINCENZO | G13: {=_xlfn.XLOOKUP($A13,'Part 1'!$A$2:$A$4305,INDEX('Part 1'!$A$2:$AG$4305,0,MATCH(G$1,'Part 1'!$1:$1,0)))} -> ROGNONI | H13: {=_xlfn.XLOOKUP($A13,'Part 1'!$A$2:$A$4305,INDEX('Part 1'!$A$2:$AG$4305,0,MATCH(H$1,'Part 1'!$1:$1,0)))} -> M - MASCHIO | I13: {=_xlfn.XLOOKUP($A13,'Part 1'!$A$2:$A$4305,INDEX('Part 1'!$A$2:$AG$4305,0,MATCH(I$1,'Part 1'!$1:$1,0)))} -> 03311300176 | J13: {=_xlfn.XLOOKUP($A13,'Part 1'!$A$2:$A$4305,INDEX('Part 1'!$A$2:$AG$4305,0,MATCH(J$1,'Part 1'!$1:$1,0)))} -> RGNVCN64T10G388S | K13: {=_xlfn.XLOOKUP($A13,'Part 1'!$A$2:$A$4305,INDEX('Part 1'!$A$2:$AG$4305,0,MATCH(K$1,'Part 1'!$1:$1,0)))} -> 5 - LEGALE | L13: {=_xlfn.XLOOKUP($A13,'Part 1'!$A$2:$A$4305,INDEX('Part 1'!$A$2:$AG$4305,0,MATCH(L$1,'Part 1'!$1:$1,0)))} -> B157 - BRESCIA | M13: {=_xlfn.XLOOKUP($A13,'Part 1'!$A$2:$A$4305,INDEX('Part 1'!$A$2:$AG$4305,0,MATCH(M$1,'Part 1'!$1:$1,0)))} -> BS | ... AG13: {=_xlfn.XLOOKUP($A13,'Part 1'!$A$2:$A$4305,INDEX('Part 1'!$A$2:$AG$4305,0,MATCH(AG$1,'Part 1'!$1:$1,0)))} -> 30 - Soggetto a IVA 22, R.A. e 4% Cassa Non Esente | AH13: Calcolato | AI13: =IF(D13="","",IF(COUNTIF('Periti SOL'!$A:$A,VALUE(D13))>0,IF(AH13="Calcolato","ERRORE: ID calcolato NON disponibile","OK - preesistente nei DB"),"OK")) -> OK | AJ13: =IF(D13="","",IF(LEFT(D13&"",1)=LEFT(C13&"",1),"OK","ERRORE: primo carattere diverso da TipoPerito")) -> OK
A14: 0328 | B14: =_xlfn.XLOOKUP(A14,'Part 1'!A:A,'Part 1'!B:B) -> 0 - PERSONA GIURIDICA | C14: =_xlfn.XLOOKUP(A14,'Part 1'!A:A,'Part 1'!C:C) -> 5 - LEGALE | D14: 50017 | E14: {=_xlfn.XLOOKUP(A14,'Part 1'!$A$2:$A$4305,INDEX('Part 1'!$A$2:$AG$4305,0,MATCH(E$1,'Part 1'!$1:$1,0)))} -> 0 - NO | F14: {=_xlfn.XLOOKUP($A14,'Part 1'!$A$2:$A$4305,INDEX('Part 1'!$A$2:$AG$4305,0,MATCH(F$1,'Part 1'!$1:$1,0)))} -> 0 | G14: {=_xlfn.XLOOKUP($A14,'Part 1'!$A$2:$A$4305,INDEX('Part 1'!$A$2:$AG$4305,0,MATCH(G$1,'Part 1'!$1:$1,0)))} -> SPAGNOLO STUDIO LEGALE ASSOCIATO | H14: {=_xlfn.XLOOKUP($A14,'Part 1'!$A$2:$A$4305,INDEX('Part 1'!$A$2:$AG$4305,0,MATCH(H$1,'Part 1'!$1:$1,0)))} -> S - SOCIETA | I14: {=_xlfn.XLOOKUP($A14,'Part 1'!$A$2:$A$4305,INDEX('Part 1'!$A$2:$AG$4305,0,MATCH(I$1,'Part 1'!$1:$1,0)))} -> 04016560874 | J14: {=_xlfn.XLOOKUP($A14,'Part 1'!$A$2:$A$4305,INDEX('Part 1'!$A$2:$AG$4305,0,MATCH(J$1,'Part 1'!$1:$1,0)))} -> 04016560874 | K14: {=_xlfn.XLOOKUP($A14,'Part 1'!$A$2:$A$4305,INDEX('Part 1'!$A$2:$AG$4305,0,MATCH(K$1,'Part 1'!$1:$1,0)))} -> 5 - LEGALE | L14: {=_xlfn.XLOOKUP($A14,'Part 1'!$A$2:$A$4305,INDEX('Part 1'!$A$2:$AG$4305,0,MATCH(L$1,'Part 1'!$1:$1,0)))} -> C351 - CATANIA | M14: {=_xlfn.XLOOKUP($A14,'Part 1'!$A$2:$A$4305,INDEX('Part 1'!$A$2:$AG$4305,0,MATCH(M$1,'Part 1'!$1:$1,0)))} -> CT | ... AG14: {=_xlfn.XLOOKUP($A14,'Part 1'!$A$2:$A$4305,INDEX('Part 1'!$A$2:$AG$4305,0,MATCH(AG$1,'Part 1'!$1:$1,0)))} -> 30 - Soggetto a IVA 22, R.A. e 4% Cassa Non Esente | AH14: Calcolato | AI14: =IF(D14="","",IF(COUNTIF('Periti SOL'!$A:$A,VALUE(D14))>0,IF(AH14="Calcolato","ERRORE: ID calcolato NON disponibile","OK - preesistente nei DB"),"OK")) -> OK | AJ14: =IF(D14="","",IF(LEFT(D14&"",1)=LEFT(C14&"",1),"OK","ERRORE: primo carattere diverso da TipoPerito")) -> OK
... A265: 10017197 | B265: =_xlfn.XLOOKUP(A265,'Part 1'!A:A,'Part 1'!B:B) -> 1 - PERSONA FISICA | C265: =_xlfn.XLOOKUP(A265,'Part 1'!A:A,'Part 1'!C:C) -> 1 - AUTO | D265: 10160 | E265: {=_xlfn.XLOOKUP(A265,'Part 1'!$A$2:$A$4305,INDEX('Part 1'!$A$2:$AG$4305,0,MATCH(E$1,'Part 1'!$1:$1,0)))} -> 0 - NO | F265: {=_xlfn.XLOOKUP($A265,'Part 1'!$A$2:$A$4305,INDEX('Part 1'!$A$2:$AG$4305,0,MATCH(F$1,'Part 1'!$1:$1,0)))} -> 0 | G265: {=_xlfn.XLOOKUP($A265,'Part 1'!$A$2:$A$4305,INDEX('Part 1'!$A$2:$AG$4305,0,MATCH(G$1,'Part 1'!$1:$1,0)))} -> MARTINELLI PIER LUIGI | H265: {=_xlfn.XLOOKUP($A265,'Part 1'!$A$2:$A$4305,INDEX('Part 1'!$A$2:$AG$4305,0,MATCH(H$1,'Part 1'!$1:$1,0)))} -> 0 | I265: {=_xlfn.XLOOKUP($A265,'Part 1'!$A$2:$A$4305,INDEX('Part 1'!$A$2:$AG$4305,0,MATCH(I$1,'Part 1'!$1:$1,0)))} -> 01056900465 | J265: {=_xlfn.XLOOKUP($A265,'Part 1'!$A$2:$A$4305,INDEX('Part 1'!$A$2:$AG$4305,0,MATCH(J$1,'Part 1'!$1:$1,0)))} -> MRTPLG57T20B455J | K265: {=_xlfn.XLOOKUP($A265,'Part 1'!$A$2:$A$4305,INDEX('Part 1'!$A$2:$AG$4305,0,MATCH(K$1,'Part 1'!$1:$1,0)))} -> 1 - AUTO | L265: {=_xlfn.XLOOKUP($A265,'Part 1'!$A$2:$A$4305,INDEX('Part 1'!$A$2:$AG$4305,0,MATCH(L$1,'Part 1'!$1:$1,0)))} -> B455 - CAMAIORE | M265: {=_xlfn.XLOOKUP($A265,'Part 1'!$A$2:$A$4305,INDEX('Part 1'!$A$2:$AG$4305,0,MATCH(M$1,'Part 1'!$1:$1,0)))} -> LU | ... AG265: {=_xlfn.XLOOKUP($A265,'Part 1'!$A$2:$A$4305,INDEX('Part 1'!$A$2:$AG$4305,0,MATCH(AG$1,'Part 1'!$1:$1,0)))} -> 49 - NO IVA BERSANI, 4% INPS NON ESENTE | AH265: Calcolato | AI265: =IF(D265="","",IF(COUNTIF('Periti SOL'!$A:$A,VALUE(D265))>0,IF(AH265="Calcolato","ERRORE: ID calcolato NON disponibile","OK - preesistente nei DB"),"OK")) -> OK | AJ265: =IF(D265="","",IF(LEFT(D265&"",1)=LEFT(C265&"",1),"OK","ERRORE: primo carattere diverso da TipoPerito")) -> OK
A266: 10060 | B266: =_xlfn.XLOOKUP(A266,'Part 1'!A:A,'Part 1'!B:B) -> 0 - PERSONA GIURIDICA | C266: =_xlfn.XLOOKUP(A266,'Part 1'!A:A,'Part 1'!C:C) -> 1 - AUTO | D266: =_xlfn.XLOOKUP(A266,'Part 1'!A:A,'Part 1'!D:D) -> 10060 | E266: {=_xlfn.XLOOKUP(A266,'Part 1'!$A$2:$A$4305,INDEX('Part 1'!$A$2:$AG$4305,0,MATCH(E$1,'Part 1'!$1:$1,0)))} -> 0 - NO | F266: {=_xlfn.XLOOKUP(B266,'Part 1'!$A$2:$A$4305,INDEX('Part 1'!$A$2:$AG$4305,0,MATCH($E1,'Part 1'!$1:$1,0)))} -> #N/A | G266: =MATCH(E1,'Part 1'!1:1,0) -> 5 | AH266: Preesistente | AI266: =IF(D266="","",IF(COUNTIF('Periti SOL'!$A:$A,VALUE(D266))>0,IF(AH266="Calcolato","ERRORE: ID calcolato NON disponibile","OK - preesistente nei DB"),"OK")) -> OK - preesistente nei DB | AJ266: =IF(D266="","",IF(LEFT(D266&"",1)=LEFT(C266&"",1),"OK","ERRORE: primo carattere diverso da TipoPerito")) -> OK
A267: 10072 | B267: =_xlfn.XLOOKUP(A267,'Part 1'!A:A,'Part 1'!B:B) -> 0 - PERSONA GIURIDICA | C267: =_xlfn.XLOOKUP(A267,'Part 1'!A:A,'Part 1'!C:C) -> 1 - AUTO | D267: =_xlfn.XLOOKUP(A267,'Part 1'!A:A,'Part 1'!D:D) -> 10072 | E267: {=_xlfn.XLOOKUP(A267,'Part 1'!$A$2:$A$4305,INDEX('Part 1'!$A$2:$AG$4305,0,MATCH(E$1,'Part 1'!$1:$1,0)))} -> 0 - NO | AH267: Preesistente | AI267: =IF(D267="","",IF(COUNTIF('Periti SOL'!$A:$A,VALUE(D267))>0,IF(AH267="Calcolato","ERRORE: ID calcolato NON disponibile","OK - preesistente nei DB"),"OK")) -> OK - preesistente nei DB | AJ267: =IF(D267="","",IF(LEFT(D267&"",1)=LEFT(C267&"",1),"OK","ERRORE: primo carattere diverso da TipoPerito")) -> OK
A268: 10103 | B268: =_xlfn.XLOOKUP(A268,'Part 1'!A:A,'Part 1'!B:B) -> 1 - PERSONA FISICA | C268: =_xlfn.XLOOKUP(A268,'Part 1'!A:A,'Part 1'!C:C) -> 1 - AUTO | D268: =_xlfn.XLOOKUP(A268,'Part 1'!A:A,'Part 1'!D:D) -> 10103 | E268: {=_xlfn.XLOOKUP(A268,'Part 1'!$A$2:$A$4305,INDEX('Part 1'!$A$2:$AG$4305,0,MATCH(E$1,'Part 1'!$1:$1,0)))} -> 0 - NO | AH268: Preesistente | AI268: =IF(D268="","",IF(COUNTIF('Periti SOL'!$A:$A,VALUE(D268))>0,IF(AH268="Calcolato","ERRORE: ID calcolato NON disponibile","OK - preesistente nei DB"),"OK")) -> OK - preesistente nei DB | AJ268: =IF(D268="","",IF(LEFT(D268&"",1)=LEFT(C268&"",1),"OK","ERRORE: primo carattere diverso da TipoPerito")) -> OK
A269: 10106 | B269: =_xlfn.XLOOKUP(A269,'Part 1'!A:A,'Part 1'!B:B) -> 0 - PERSONA GIURIDICA | C269: =_xlfn.XLOOKUP(A269,'Part 1'!A:A,'Part 1'!C:C) -> 1 - AUTO | D269: =_xlfn.XLOOKUP(A269,'Part 1'!A:A,'Part 1'!D:D) -> 10106 | E269: {=_xlfn.XLOOKUP(A269,'Part 1'!$A$2:$A$4305,INDEX('Part 1'!$A$2:$AG$4305,0,MATCH(E$1,'Part 1'!$1:$1,0)))} -> 0 - NO | AH269: Preesistente | AI269: =IF(D269="","",IF(COUNTIF('Periti SOL'!$A:$A,VALUE(D269))>0,IF(AH269="Calcolato","ERRORE: ID calcolato NON disponibile","OK - preesistente nei DB"),"OK")) -> OK - preesistente nei DB | AJ269: =IF(D269="","",IF(LEFT(D269&"",1)=LEFT(C269&"",1),"OK","ERRORE: primo carattere diverso da TipoPerito")) -> OK
A270: 10115 | B270: =_xlfn.XLOOKUP(A270,'Part 1'!A:A,'Part 1'!B:B) -> 0 - PERSONA GIURIDICA | C270: =_xlfn.XLOOKUP(A270,'Part 1'!A:A,'Part 1'!C:C) -> 1 - AUTO | D270: =_xlfn.XLOOKUP(A270,'Part 1'!A:A,'Part 1'!D:D) -> 10115 | E270: {=_xlfn.XLOOKUP(A270,'Part 1'!$A$2:$A$4305,INDEX('Part 1'!$A$2:$AG$4305,0,MATCH(E$1,'Part 1'!$1:$1,0)))} -> 0 - NO | AH270: Preesistente | AI270: =IF(D270="","",IF(COUNTIF('Periti SOL'!$A:$A,VALUE(D270))>0,IF(AH270="Calcolato","ERRORE: ID calcolato NON disponibile","OK - preesistente nei DB"),"OK")) -> OK - preesistente nei DB | AJ270: =IF(D270="","",IF(LEFT(D270&"",1)=LEFT(C270&"",1),"OK","ERRORE: primo carattere diverso da TipoPerito")) -> OK
A271: 1012 | B271: =_xlfn.XLOOKUP(A271,'Part 1'!A:A,'Part 1'!B:B) -> 0 - PERSONA GIURIDICA | C271: =_xlfn.XLOOKUP(A271,'Part 1'!A:A,'Part 1'!C:C) -> 5 - LEGALE | D271: 50149 | E271: {=_xlfn.XLOOKUP(A271,'Part 1'!$A$2:$A$4305,INDEX('Part 1'!$A$2:$AG$4305,0,MATCH(E$1,'Part 1'!$1:$1,0)))} -> 0 - NO | AH271: Calcolato | AI271: =IF(D271="","",IF(COUNTIF('Periti SOL'!$A:$A,VALUE(D271))>0,IF(AH271="Calcolato","ERRORE: ID calcolato NON disponibile","OK - preesistente nei DB"),"OK")) -> OK | AJ271: =IF(D271="","",IF(LEFT(D271&"",1)=LEFT(C271&"",1),"OK","ERRORE: primo carattere diverso da TipoPerito")) -> OK
A272: 1013 | B272: =_xlfn.XLOOKUP(A272,'Part 1'!A:A,'Part 1'!B:B) -> 1 - PERSONA FISICA | C272: =_xlfn.XLOOKUP(A272,'Part 1'!A:A,'Part 1'!C:C) -> 5 - LEGALE | D272: 50151 | E272: {=_xlfn.XLOOKUP(A272,'Part 1'!$A$2:$A$4305,INDEX('Part 1'!$A$2:$AG$4305,0,MATCH(E$1,'Part 1'!$1:$1,0)))} -> 0 - NO | AH272: Calcolato | AI272: =IF(D272="","",IF(COUNTIF('Periti SOL'!$A:$A,VALUE(D272))>0,IF(AH272="Calcolato","ERRORE: ID calcolato NON disponibile","OK - preesistente nei DB"),"OK")) -> OK | AJ272: =IF(D272="","",IF(LEFT(D272&"",1)=LEFT(C272&"",1),"OK","ERRORE: primo carattere diverso da TipoPerito")) -> OK
A273: 1014 | B273: =_xlfn.XLOOKUP(A273,'Part 1'!A:A,'Part 1'!B:B) -> 1 - PERSONA FISICA | C273: =_xlfn.XLOOKUP(A273,'Part 1'!A:A,'Part 1'!C:C) -> 4 - MEDICO | D273: 40305 | E273: {=_xlfn.XLOOKUP(A273,'Part 1'!$A$2:$A$4305,INDEX('Part 1'!$A$2:$AG$4305,0,MATCH(E$1,'Part 1'!$1:$1,0)))} -> 0 - NO | AH273: Calcolato | AI273: =IF(D273="","",IF(COUNTIF('Periti SOL'!$A:$A,VALUE(D273))>0,IF(AH273="Calcolato","ERRORE: ID calcolato NON disponibile","OK - preesistente nei DB"),"OK")) -> OK | AJ273: =IF(D273="","",IF(LEFT(D273&"",1)=LEFT(C273&"",1),"OK","ERRORE: primo carattere diverso da TipoPerito")) -> OK
A274: 1015 | B274: =_xlfn.XLOOKUP(A274,'Part 1'!A:A,'Part 1'!B:B) -> 1 - PERSONA FISICA | C274: =_xlfn.XLOOKUP(A274,'Part 1'!A:A,'Part 1'!C:C) -> 1 - AUTO | D274: 10161 | E274: {=_xlfn.XLOOKUP(A274,'Part 1'!$A$2:$A$4305,INDEX('Part 1'!$A$2:$AG$4305,0,MATCH(E$1,'Part 1'!$1:$1,0)))} -> 0 - NO | AH274: Calcolato | AI274: =IF(D274="","",IF(COUNTIF('Periti SOL'!$A:$A,VALUE(D274))>0,IF(AH274="Calcolato","ERRORE: ID calcolato NON disponibile","OK - preesistente nei DB"),"OK")) -> OK | AJ274: =IF(D274="","",IF(LEFT(D274&"",1)=LEFT(C274&"",1),"OK","ERRORE: primo carattere diverso da TipoPerito")) -> OK
A275: 1018 | B275: =_xlfn.XLOOKUP(A275,'Part 1'!A:A,'Part 1'!B:B) -> 1 - PERSONA FISICA | C275: =_xlfn.XLOOKUP(A275,'Part 1'!A:A,'Part 1'!C:C) -> 1 - AUTO | D275: 10162 | E275: {=_xlfn.XLOOKUP(A275,'Part 1'!$A$2:$A$4305,INDEX('Part 1'!$A$2:$AG$4305,0,MATCH(E$1,'Part 1'!$1:$1,0)))} -> 0 - NO | AH275: Calcolato | AI275: =IF(D275="","",IF(COUNTIF('Periti SOL'!$A:$A,VALUE(D275))>0,IF(AH275="Calcolato","ERRORE: ID calcolato NON disponibile","OK - preesistente nei DB"),"OK")) -> OK | AJ275: =IF(D275="","",IF(LEFT(D275&"",1)=LEFT(C275&"",1),"OK","ERRORE: primo carattere diverso da TipoPerito")) -> OK
A276: 1019 | B276: =_xlfn.XLOOKUP(A276,'Part 1'!A:A,'Part 1'!B:B) -> 1 - PERSONA FISICA | C276: =_xlfn.XLOOKUP(A276,'Part 1'!A:A,'Part 1'!C:C) -> 4 - MEDICO | D276: 40338 | E276: {=_xlfn.XLOOKUP(A276,'Part 1'!$A$2:$A$4305,INDEX('Part 1'!$A$2:$AG$4305,0,MATCH(E$1,'Part 1'!$1:$1,0)))} -> 0 - NO | AH276: Calcolato | AI276: =IF(D276="","",IF(COUNTIF('Periti SOL'!$A:$A,VALUE(D276))>0,IF(AH276="Calcolato","ERRORE: ID calcolato NON disponibile","OK - preesistente nei DB"),"OK")) -> OK | AJ276: =IF(D276="","",IF(LEFT(D276&"",1)=LEFT(C276&"",1),"OK","ERRORE: primo carattere diverso da TipoPerito")) -> OK
A277: 10191 | B277: =_xlfn.XLOOKUP(A277,'Part 1'!A:A,'Part 1'!B:B) -> 1 - PERSONA FISICA | C277: =_xlfn.XLOOKUP(A277,'Part 1'!A:A,'Part 1'!C:C) -> 1 - AUTO | D277: =_xlfn.XLOOKUP(A277,'Part 1'!A:A,'Part 1'!D:D) -> 10191 | E277: {=_xlfn.XLOOKUP(A277,'Part 1'!$A$2:$A$4305,INDEX('Part 1'!$A$2:$AG$4305,0,MATCH(E$1,'Part 1'!$1:$1,0)))} -> 0 - NO | AH277: Preesistente | AI277: =IF(D277="","",IF(COUNTIF('Periti SOL'!$A:$A,VALUE(D277))>0,IF(AH277="Calcolato","ERRORE: ID calcolato NON disponibile","OK - preesistente nei DB"),"OK")) -> OK - preesistente nei DB | AJ277: =IF(D277="","",IF(LEFT(D277&"",1)=LEFT(C277&"",1),"OK","ERRORE: primo carattere diverso da TipoPerito")) -> OK
A278: 1022 | B278: =_xlfn.XLOOKUP(A278,'Part 1'!A:A,'Part 1'!B:B) -> 1 - PERSONA FISICA | C278: =_xlfn.XLOOKUP(A278,'Part 1'!A:A,'Part 1'!C:C) -> 4 - MEDICO | D278: 40339 | E278: {=_xlfn.XLOOKUP(A278,'Part 1'!$A$2:$A$4305,INDEX('Part 1'!$A$2:$AG$4305,0,MATCH(E$1,'Part 1'!$1:$1,0)))} -> 0 - NO | AH278: Calcolato | AI278: =IF(D278="","",IF(COUNTIF('Periti SOL'!$A:$A,VALUE(D278))>0,IF(AH278="Calcolato","ERRORE: ID calcolato NON disponibile","OK - preesistente nei DB"),"OK")) -> OK | AJ278: =IF(D278="","",IF(LEFT(D278&"",1)=LEFT(C278&"",1),"OK","ERRORE: primo carattere diverso da TipoPerito")) -> OK
A279: 10220 | B279: =_xlfn.XLOOKUP(A279,'Part 1'!A:A,'Part 1'!B:B) -> 1 - PERSONA FISICA | C279: =_xlfn.XLOOKUP(A279,'Part 1'!A:A,'Part 1'!C:C) -> 1 - AUTO | D279: =_xlfn.XLOOKUP(A279,'Part 1'!A:A,'Part 1'!D:D) -> 10220 | E279: {=_xlfn.XLOOKUP(A279,'Part 1'!$A$2:$A$4305,INDEX('Part 1'!$A$2:$AG$4305,0,MATCH(E$1,'Part 1'!$1:$1,0)))} -> 0 - NO | AH279: Preesistente | AI279: =IF(D279="","",IF(COUNTIF('Periti SOL'!$A:$A,VALUE(D279))>0,IF(AH279="Calcolato","ERRORE: ID calcolato NON disponibile","OK - preesistente nei DB"),"OK")) -> OK - preesistente nei DB | AJ279: =IF(D279="","",IF(LEFT(D279&"",1)=LEFT(C279&"",1),"OK","ERRORE: primo carattere diverso da TipoPerito")) -> OK
A280: 10225 | B280: =_xlfn.XLOOKUP(A280,'Part 1'!A:A,'Part 1'!B:B) -> 0 - PERSONA GIURIDICA | C280: =_xlfn.XLOOKUP(A280,'Part 1'!A:A,'Part 1'!C:C) -> 1 - AUTO | D280: =_xlfn.XLOOKUP(A280,'Part 1'!A:A,'Part 1'!D:D) -> 10225 | E280: {=_xlfn.XLOOKUP(A280,'Part 1'!$A$2:$A$4305,INDEX('Part 1'!$A$2:$AG$4305,0,MATCH(E$1,'Part 1'!$1:$1,0)))} -> 0 - NO | AH280: Preesistente | AI280: =IF(D280="","",IF(COUNTIF('Periti SOL'!$A:$A,VALUE(D280))>0,IF(AH280="Calcolato","ERRORE: ID calcolato NON disponibile","OK - preesistente nei DB"),"OK")) -> OK - preesistente nei DB | AJ280: =IF(D280="","",IF(LEFT(D280&"",1)=LEFT(C280&"",1),"OK","ERRORE: primo carattere diverso da TipoPerito")) -> OK
A281: 10256 | B281: =_xlfn.XLOOKUP(A281,'Part 1'!A:A,'Part 1'!B:B) -> 1 - PERSONA FISICA | C281: =_xlfn.XLOOKUP(A281,'Part 1'!A:A,'Part 1'!C:C) -> 1 - AUTO | D281: =_xlfn.XLOOKUP(A281,'Part 1'!A:A,'Part 1'!D:D) -> 10256 | E281: {=_xlfn.XLOOKUP(A281,'Part 1'!$A$2:$A$4305,INDEX('Part 1'!$A$2:$AG$4305,0,MATCH(E$1,'Part 1'!$1:$1,0)))} -> 0 - NO | AH281: Preesistente | AI281: =IF(D281="","",IF(COUNTIF('Periti SOL'!$A:$A,VALUE(D281))>0,IF(AH281="Calcolato","ERRORE: ID calcolato NON disponibile","OK - preesistente nei DB"),"OK")) -> OK - preesistente nei DB | AJ281: =IF(D281="","",IF(LEFT(D281&"",1)=LEFT(C281&"",1),"OK","ERRORE: primo carattere diverso da TipoPerito")) -> OK
A282: 10266 | B282: =_xlfn.XLOOKUP(A282,'Part 1'!A:A,'Part 1'!B:B) -> 0 - PERSONA GIURIDICA | C282: =_xlfn.XLOOKUP(A282,'Part 1'!A:A,'Part 1'!C:C) -> 1 - AUTO | D282: 10164 | E282: {=_xlfn.XLOOKUP(A282,'Part 1'!$A$2:$A$4305,INDEX('Part 1'!$A$2:$AG$4305,0,MATCH(E$1,'Part 1'!$1:$1,0)))} -> 0 - NO | AH282: Calcolato | AI282: =IF(D282="","",IF(COUNTIF('Periti SOL'!$A:$A,VALUE(D282))>0,IF(AH282="Calcolato","ERRORE: ID calcolato NON disponibile","OK - preesistente nei DB"),"OK")) -> OK | AJ282: =IF(D282="","",IF(LEFT(D282&"",1)=LEFT(C282&"",1),"OK","ERRORE: primo carattere diverso da TipoPerito")) -> OK
A283: 1029 | B283: =_xlfn.XLOOKUP(A283,'Part 1'!A:A,'Part 1'!B:B) -> 1 - PERSONA FISICA | C283: =_xlfn.XLOOKUP(A283,'Part 1'!A:A,'Part 1'!C:C) -> 4 - MEDICO | D283: 40410 | E283: {=_xlfn.XLOOKUP(A283,'Part 1'!$A$2:$A$4305,INDEX('Part 1'!$A$2:$AG$4305,0,MATCH(E$1,'Part 1'!$1:$1,0)))} -> 0 - NO | AH283: Calcolato | AI283: =IF(D283="","",IF(COUNTIF('Periti SOL'!$A:$A,VALUE(D283))>0,IF(AH283="Calcolato","ERRORE: ID calcolato NON disponibile","OK - preesistente nei DB"),"OK")) -> OK | AJ283: =IF(D283="","",IF(LEFT(D283&"",1)=LEFT(C283&"",1),"OK","ERRORE: primo carattere diverso da TipoPerito")) -> OK
A284: 1030 | B284: =_xlfn.XLOOKUP(A284,'Part 1'!A:A,'Part 1'!B:B) -> 1 - PERSONA FISICA | C284: =_xlfn.XLOOKUP(A284,'Part 1'!A:A,'Part 1'!C:C) -> 4 - MEDICO | D284: 40411 | E284: {=_xlfn.XLOOKUP(A284,'Part 1'!$A$2:$A$4305,INDEX('Part 1'!$A$2:$AG$4305,0,MATCH(E$1,'Part 1'!$1:$1,0)))} -> 0 - NO | AH284: Calcolato | AI284: =IF(D284="","",IF(COUNTIF('Periti SOL'!$A:$A,VALUE(D284))>0,IF(AH284="Calcolato","ERRORE: ID calcolato NON disponibile","OK - preesistente nei DB"),"OK")) -> OK | AJ284: =IF(D284="","",IF(LEFT(D284&"",1)=LEFT(C284&"",1),"OK","ERRORE: primo carattere diverso da TipoPerito")) -> OK
A285: 10304 | B285: =_xlfn.XLOOKUP(A285,'Part 1'!A:A,'Part 1'!B:B) -> 0 - PERSONA GIURIDICA | C285: =_xlfn.XLOOKUP(A285,'Part 1'!A:A,'Part 1'!C:C) -> 1 - AUTO | D285: =_xlfn.XLOOKUP(A285,'Part 1'!A:A,'Part 1'!D:D) -> 10304 | E285: {=_xlfn.XLOOKUP(A285,'Part 1'!$A$2:$A$4305,INDEX('Part 1'!$A$2:$AG$4305,0,MATCH(E$1,'Part 1'!$1:$1,0)))} -> 0 - NO | AH285: Preesistente | AI285: =IF(D285="","",IF(COUNTIF('Periti SOL'!$A:$A,VALUE(D285))>0,IF(AH285="Calcolato","ERRORE: ID calcolato NON disponibile","OK - preesistente nei DB"),"OK")) -> OK - preesistente nei DB | AJ285: =IF(D285="","",IF(LEFT(D285&"",1)=LEFT(C285&"",1),"OK","ERRORE: primo carattere diverso da TipoPerito")) -> OK
A286: 1032 | B286: =_xlfn.XLOOKUP(A286,'Part 1'!A:A,'Part 1'!B:B) -> 1 - PERSONA FISICA | C286: =_xlfn.XLOOKUP(A286,'Part 1'!A:A,'Part 1'!C:C) -> 5 - LEGALE | D286: 50155 | E286: {=_xlfn.XLOOKUP(A286,'Part 1'!$A$2:$A$4305,INDEX('Part 1'!$A$2:$AG$4305,0,MATCH(E$1,'Part 1'!$1:$1,0)))} -> 0 - NO | AH286: Calcolato | AI286: =IF(D286="","",IF(COUNTIF('Periti SOL'!$A:$A,VALUE(D286))>0,IF(AH286="Calcolato","ERRORE: ID calcolato NON disponibile","OK - preesistente nei DB"),"OK")) -> OK | AJ286: =IF(D286="","",IF(LEFT(D286&"",1)=LEFT(C286&"",1),"OK","ERRORE: primo carattere diverso da TipoPerito")) -> OK
A287: 1035 | B287: =_xlfn.XLOOKUP(A287,'Part 1'!A:A,'Part 1'!B:B) -> 1 - PERSONA FISICA | C287: =_xlfn.XLOOKUP(A287,'Part 1'!A:A,'Part 1'!C:C) -> 4 - MEDICO | D287: 40442 | E287: {=_xlfn.XLOOKUP(A287,'Part 1'!$A$2:$A$4305,INDEX('Part 1'!$A$2:$AG$4305,0,MATCH(E$1,'Part 1'!$1:$1,0)))} -> 0 - NO | AH287: Calcolato | AI287: =IF(D287="","",IF(COUNTIF('Periti SOL'!$A:$A,VALUE(D287))>0,IF(AH287="Calcolato","ERRORE: ID calcolato NON disponibile","OK - preesistente nei DB"),"OK")) -> OK | AJ287: =IF(D287="","",IF(LEFT(D287&"",1)=LEFT(C287&"",1),"OK","ERRORE: primo carattere diverso da TipoPerito")) -> OK
A288: 10356 | B288: =_xlfn.XLOOKUP(A288,'Part 1'!A:A,'Part 1'!B:B) -> 1 - PERSONA FISICA | C288: =_xlfn.XLOOKUP(A288,'Part 1'!A:A,'Part 1'!C:C) -> 1 - AUTO | D288: =_xlfn.XLOOKUP(A288,'Part 1'!A:A,'Part 1'!D:D) -> 10356 | E288: {=_xlfn.XLOOKUP(A288,'Part 1'!$A$2:$A$4305,INDEX('Part 1'!$A$2:$AG$4305,0,MATCH(E$1,'Part 1'!$1:$1,0)))} -> 0 - NO | AH288: Preesistente | AI288: =IF(D288="","",IF(COUNTIF('Periti SOL'!$A:$A,VALUE(D288))>0,IF(AH288="Calcolato","ERRORE: ID calcolato NON disponibile","OK - preesistente nei DB"),"OK")) -> OK - preesistente nei DB | AJ288: =IF(D288="","",IF(LEFT(D288&"",1)=LEFT(C288&"",1),"OK","ERRORE: primo carattere diverso da TipoPerito")) -> OK
A289: 1037 | B289: =_xlfn.XLOOKUP(A289,'Part 1'!A:A,'Part 1'!B:B) -> 0 - PERSONA GIURIDICA | C289: =_xlfn.XLOOKUP(A289,'Part 1'!A:A,'Part 1'!C:C) -> 1 - AUTO | D289: 10165 | E289: {=_xlfn.XLOOKUP(A289,'Part 1'!$A$2:$A$4305,INDEX('Part 1'!$A$2:$AG$4305,0,MATCH(E$1,'Part 1'!$1:$1,0)))} -> 0 - NO | AH289: Calcolato | AI289: =IF(D289="","",IF(COUNTIF('Periti SOL'!$A:$A,VALUE(D289))>0,IF(AH289="Calcolato","ERRORE: ID calcolato NON disponibile","OK - preesistente nei DB"),"OK")) -> OK | AJ289: =IF(D289="","",IF(LEFT(D289&"",1)=LEFT(C289&"",1),"OK","ERRORE: primo carattere diverso da TipoPerito")) -> OK
